Workbook

Sheet 总览
A1: 统一异构 KVCache 存储池｜全量需求树 V2.3.1（SR 独立交付重构评审版）
A2: SF → IR → SR → AR｜38 个可独立交付 SR 功能闭包｜149 条来源需求全量追溯｜2026-07-24
A4: 重构结论：IR 保持 24 条；SR 不再与来源需求逐行一一对应，而按组件/插件/服务/工具等独立交付功能闭包聚合；AR 按真实复杂度拆为 3～6 个工作包。
A6: SF | D6: IR | G6: SR 功能闭包 | J6: AR 工作包
A7: 2 | D7: 24 | G7: 38 | J7: 203
A10: SF-01｜统一池与语义化传输底座 | G10: SF-02｜集群复用与推理 SLO 闭环
A11: 以 KV对象（KVObject）、存储区段清单（ExtentManifest）、放置位置（Placement）、能力矩阵（CapabilityMatrix） 与 查询计划（QueryPlan） 为统一抽象，交付可组合的异构存储池、传输后端、状态一致性与安全数据面。 验收：五类介质可纳管；至少一条 HBM↔SSD 容量主路径闭环；错误/过期 KV 消费为 0；主路径 主机有效载荷访问（Host Payload touch）=0。 | G11: 面向 vLLM/SGLang 交付可消费命中、加载决策、目录、调度、预取、观测与工程化能力，把存储和传输收益兑现为 TTFT、TPOT、容量及 NPU 利用率。 验收：目标工作负载 p99 TTFT 降低≥20%；TPOT p99 回退<3%；可用命中率（Usable Hit Rate） 提升≥20%；HBM 有效容量提升≥30%。
A16: 评审入口
A17: SF-IR骨架｜24条初始需求/技术锚点 | G17: SR系统设计｜38个独立交付功能闭包
A18: 全量层级树｜浏览 SF→IR→SR→AR | G18: AR开发认领｜3～6个真实工作包/SR
A19: 追溯与覆盖｜149条来源多对一映射 | G19: SR依赖矩阵｜依赖、桩件和独立交付判定
A20: 质量门禁｜独立交付与全量追溯公式检查 | G20: V2.3.1整改说明｜本轮语义与结构变化

Sheet SF-IR骨架
A1: SF—IR 技术骨架（V2.3.1 SR 独立交付重构）
A2: 24 条 IR 保持 V2.2 语义与 KPI；最后一列改为统计新的 SR 功能闭包数量。
A4: IR ID | B4: SF ID | C4: SF 技术特性 | D4: IR 技术域（功能化描述） | E4: 具体依赖库/核心组件/底层机制 | F4: IR 功能/性能实现预期 | G4: 确定性 KPI / 建议门槛 | H4: 主技术模块 | I4: 关键输入 | J4: 关键输出 | K4: 失败/降级语义 | L4: 冻结状态 | M4: V2.3.1 SR 数
A5: IR-01-01 | B5: SF-01 | C5: 提供可编程、可寻址、可执行的统一异构 KVCache 存储池 | D5: 支持HBM、DDR、SSD及远端介质统一纳管，并以HBM↔SSD构建容量主路径 | E5: KV对象（KVObject）/存储区段清单（ExtentManifest） + 页/存储区段分配器（Page/Extent Allocator） + HBM↔SSD Capacity Path + DDR 角色策略（RolePolicy） | F5: 系统应以统一 KV对象（KVObject） 接口纳管 HBM、本地/远端 DDR、本地/远端 SSD/object 中的 KVCache，并把 HBM↔SSD 直达或低 Host 参与通路作为扩展容量的默认主路径。DDR不是必须经过的中间层，只能在 温数据层（warm）、预取/突发（prefetch/burst）、远端共享或 注册内存池（registered-pool） 等经实测有净收益的角色中启用；系统应依据水位、访问时限、复用收益和路径能力完成放置、迁移、淘汰与空间整理。 | G5: 碎片率<5%；HBM有效容量提升≥30%；OOM/抢占（preemption）降低≥50%；HBM↔SSD容量路径有效带宽≥设备峰值80%；DDR角色必须至少一项持续正收益，否则退出有效载荷（Payload）主路径。 | H5: TM3 | I5: KV访问意图（KVAccessIntent） + KV块规格（KVBlockSpec） + 存储层级（tier）/path 遥测数据（telemetry） | J5: KVObjectHandle + 放置位置（Placement） + 状态转换（state transition） + DDR 角色决策（role decision） | K5: OOM/碎片/路径不可用时拒绝、直接下沉SSD或重算；DDR无正收益时仅保留元数据/控制（metadata/control）/必要registered pool | L5: 沿用V2.2；SR闭包重构后复核 | M5: =COUNTIF('SR系统设计'!$B$5:$B$42,A5)
A6: IR-01-02 | B6: SF-01 | C6: 提供可编程、可寻址、可执行的统一异构 KVCache 存储池 | D6: 支持vLLM/SGLang KV块跨介质批量传输的布局适配与描述生成 | E6: 存储区段清单（ExtentManifest） + 分散/聚集描述符编译器（Scatter/Gather Descriptor Compiler） + FlatBuffers/Protobuf ABI | F6: 系统应接收 vLLM 块（block）、SGLang 页/基数树区间（page/radix span） 等不同框架产生的逻辑 KV 片段，自动适配目标 HBM、DDR、SSD、RDMA 或 UBMEM 路径的内存布局和传输约束，生成可由底层一次或少量批次执行的统一传输任务。其目的不是暴露 SG、对齐或 fence 细节，而是消除逐块拷贝、重复后端适配和小 I/O 风暴，让同一份 KVCache 能在不同介质与传输后端之间高效流转。 | G6: 描述符（descriptor） 数降低≥50%；effective BW提升≥30%；CPU提交时延（CPU submit time）降低≥40%；布局协商错误=0。 | H6: TM4 | I6: KV 布局（layout） + logical spans + 目标能力（target capability） | J6: 批量描述符（BulkDescriptor） + 布局转换计划（LayoutTransformPlan） | K6: 布局不兼容时换副本、执行显式 转换（transform） 或重算；禁止隐式错误 附加（attach） | L6: 沿用V2.2；SR闭包重构后复核 | M6: =COUNTIF('SR系统设计'!$B$5:$B$42,A6)
A7: IR-01-03 | B7: SF-01 | C7: 提供可编程、可寻址、可执行的统一异构 KVCache 存储池 | D7: 面向TTFT收益与资源成本的KV访问决策和查询计划（QueryPlan）生成 | E7: 查询计划（QueryPlan） + 放置解析器（PlacementResolver） + EWMA成本模型（EWMA CostModel） + 策略引擎（PolicyEngine） | F7: 系统应在发现多个 KV 副本或访问路径后，综合请求 TTFT 截止时限（deadline）、预计重算时间、加载/附加成本、HBM 水位、路径拥塞和 TPOT 干扰，明确选择本地复用、远端加载、直接访问、回填 HBM、部分重算或完全重算，并输出包含候选位置、预估成本、执行动作和回退顺序的 查询计划（QueryPlan），确保只消费收益为正且可安全使用的 KVCache。 | G7: 可用命中率（Usable Hit Rate）提升≥20%；路径成本预测误差<20%；单次策略调用<5 μs；负收益命中强制放弃。 | H7: TM1/TM3/TM4 | I7: 候选放置位置（candidate placements） + 截止时限（deadline） + 遥测数据（telemetry） | J7: 排序后的查询计划（ranked QueryPlan） + 回退链（fallback chain） + 决策原因（decision reason） | K7: 估计不可信、超预算或路径退化时回到本地 cache/备用副本/部分重算（partial recompute）/重算（recompute） | L7: 沿用V2.2；SR闭包重构后复核 | M7: =COUNTIF('SR系统设计'!$B$5:$B$42,A7)
A8: IR-01-04 | B8: SF-01 | C8: 提供可编程、可寻址、可执行的统一异构 KVCache 存储池 | D8: 支持P/D分离、流水加载及一对多共享的异步KV传输编排 | E8: URMA/RDMA/NIXL/Mooncake 异步有向无环图（Async DAG） + Rendezvous + Multicast | F8: 系统应把 P→D 推送、D→P 拉取、目录会合、Layer/Page 流水加载和公共前缀一对多分发统一组织为异步传输流程，能够管理任务依赖、并发额度、提交顺序、完成通知、目标级结果和取消。其目的在于让 KV 数据移动与推理计算重叠，避免单目标或单阶段串行等待放大 TTFT，并允许部分目标失败时局部重试或回退。 | G8: 预填充/解码交接（P/D handoff） p99降低≥20%；热点分发p99降低≥40%；广播完成率≥99.99%；计算/传输重叠≥60%。 | H8: TM4 | I8: 查询计划（QueryPlan） + 批量描述符（BulkDescriptor） + 流量类别（traffic class） | J8: 传输票据（TransferTicket） + 完成/栅栏（completion/fence） + 每目标结果（per-target result） | K8: 部分目标失败时隔离重试；截止时限（deadline）到期取消未提交任务并按目标粒度回退 | L8: 沿用V2.2；SR闭包重构后复核 | M8: =COUNTIF('SR系统设计'!$B$5:$B$42,A8)
A9: IR-01-05 | B9: SF-01 | C9: 提供可编程、可寻址、可执行的统一异构 KVCache 存储池 | D9: 面向异构介质与集群拓扑的传输能力探测和动态路径选择 | E9: 能力矩阵（CapabilityMatrix） + hwloc/libnuma + 路径质量监视器（PathQualityMonitor） | F9: 系统应持续识别节点、NPU、NUMA、网卡、SSD及交换网络之间可用的 KV 访问路径，回答每条路径支持什么介质、布局、数据规模和传输语义，以及当前带宽、时延、队列深度和健康状态。调度和存储策略应据此动态选择代价最低且满足 截止时限（deadline） 的路径，并在拥塞或故障时及时降权、切换或禁止使用，避免静态路由造成尾时延放大。 | G9: 路径选择准确率≥90%；同机架 本地可用命中（Local Usable Hit）提升≥30%；故障切换<200ms；探测开销<0.5% BW。 | H9: TM1/TM4 | I9: 拓扑（topology） + 设备能力（device capability） + 队列遥测数据（queue telemetry） | J9: ranked path set + health state + cost | K9: 连续3次探测失败降权/摘除；无合格路径时返回明确不可达而非隐式慢路径 | L9: 沿用V2.2；SR闭包重构后复核 | M9: =COUNTIF('SR系统设计'!$B$5:$B$42,A9)
A10: IR-01-06 | B10: SF-01 | C10: 提供可编程、可寻址、可执行的统一异构 KVCache 存储池 | D10: 支持跨节点HBM/DDR零拷贝的RDMA高速KV传输 | E10: rdma-core/libibverbs + 注册内存池（RegisteredPool） + GPUDirect/NPU Direct RDMA | F10: 系统应在硬件支持时提供跨节点 HBM↔HBM、HBM↔DDR 和 DDR↔DDR 的 RDMA 零拷贝传输能力，使 KV 有效载荷（Payload） 直接在注册内存区域之间移动，不经过 CPU 缓存或额外 主机暂存（Host staging）；同时提供注册区域生命周期、远端句柄、批量提交、流控、完成和错误结果，降低跨节点加载时延与 CPU 占用。 | G10: 端到端传输时延降低≥40%；有效带宽≥链路线速80%；CPU有效载荷复制（CPU payload copy）=0；CPU提交开销<50 μs。 | H10: TM4 | I10: 已注册存储区段（registered extent） + 远端句柄（remote handle） + 描述符（descriptor） | J10: RDMA ticket + CQ completion + hardware error | K10: 注册失败、CQ超时或链路错误按策略切备用副本/URMA/TCP冷路径/重算 | L10: 沿用V2.2；SR闭包重构后复核 | M10: =COUNTIF('SR系统设计'!$B$5:$B$42,A10)
A11: IR-01-07 | B11: SF-01 | C11: 提供可编程、可寻址、可执行的统一异构 KVCache 存储池 | D11: 支持UBMEM/C2C内存语义的KV直接访问、回填与View保护 | E11: UBMEM/URMA + C2C Unified VA + mmap/madvise + DirectViewGuard | F11: 系统应在 UBMEM、URMA 或 C2C 具备合格能力的平台上，让热元数据和满足条件的 KV区间（KV span） 通过统一地址或 内存视图（memory view） 被直接访问，并能根据访问跨度、复用次数和 解码停顿（Decode stall） 风险在 直接视图（direct view） 与 复制到 HBM（copy-to-HBM） 之间选择。任何 视图（view） 都必须具备租约、可见性、撤销和回填语义，确保扩展有效容量时不以 TPOT 退化或悬空访问为代价。 | G11: 直接视图（direct-view） TPOT p99回退<3%；主机有效载荷访问（Host Payload touch）=0；陈旧视图故障（stale view fault）=0；HBM+C2C有效容量提升≥20%。 | H11: TM3/TM4 | I11: memory region + 访问模式（access mode） hint + 租约（lease） | J11: ViewHandle/CopyPlan + visibility evidence | K11: 能力不满足、租约失效或远端 停顿（stall） 超阈值时撤销 视图（view） 并 复制到 HBM（copy-to-HBM）/重算（recompute） | L11: 沿用V2.2；SR闭包重构后复核 | M11: =COUNTIF('SR系统设计'!$B$5:$B$42,A11)
A12: IR-01-08 | B12: SF-01 | C12: 提供可编程、可寻址、可执行的统一异构 KVCache 存储池 | D12: 支持HBM↔SSD直达容量I/O及条件化DPU/硬件编解码器（Codec）卸载 | E12: SPDK + io_uring + GPUDirect Storage/NPU Direct Storage + conditional DPU/hardware 编解码器（codec） | F12: 系统应把本地/远端 SSD 和 object storage 纳入 KVCache 主容量层，优先形成 HBM↔SSD 直达或低 Host 参与的大段异步 I/O；CPU仅参与控制面提交和异常诊断，不得在默认主路径承担 有效载荷（Payload） 压缩、解压或全量 CRC。DPU、硬件 编解码器（Codec） 与硬件校验仅在能力探测通过且端到端净收益为正时启用，并必须可旁路回 原始/直接（raw/direct） 路径。 | G12: SSD restore TTFT降低≥30%；NPU 停顿（stall）降低≥50%；主路径主机有效载荷访问（Host Payload touch）=0；顺序带宽达到设备峰值≥80%；条件卸载必须相对原始/直接（raw/direct）路径产生正收益。 | H12: TM4 | I12: 持久存储区段（persistent extent） + 对象键（object key） + 松弛预算（slack budget） + 硬件能力（hardware capability） | J12: I/O ticket + durability/path-integrity evidence | K12: Direct能力不可用时显式 分阶段暂存路径（staged path）并受CPU预算约束；无硬件编解码器（codec）/DPU时保持原始/直接（raw/direct）主路径，不以CPU 编解码器（codec）兜底 | L12: 沿用V2.2；SR闭包重构后复核 | M12: =COUNTIF('SR系统设计'!$B$5:$B$42,A12)
A13: IR-01-09 | B13: SF-01 | C13: 提供可编程、可寻址、可执行的统一异构 KVCache 存储池 | D13: 统一抽象UB、URMA、RDMA、C2C和SSD传输能力并按需路由 | E13: UB/URMA/RDMA/C2C/SSD 能力提供器（Capability Provider） + 后端注册表（Backend Registry） + 互联路由器（FabricRouter） | F13: 系统应以统一 能力（Capability） 模型描述 UB、URMA、RDMA、C2C、SSD/DPU 等物理能力及其软件后端，明确 HBM↔SSD 是否直达、地址可达性、注册要求、支持布局、主机有效载荷访问（Host Payload touch）、完成/错误语义和可观测字段。上层只依据标准能力选择路径，不得因实现便利静默退化为 HBM→DDR→SSD 三级串行搬运。 | G13: 能力表覆盖率=100%；错误路由=0；查询计划（QueryPlan）策略决策<5 μs；互联网络路由器（Fabric Router）路由决策<3 μs；任何 分阶段暂存（staged） 例外可见且可禁用。 | H13: TM4 | I13: 设备清单（device inventory） + 后端探测（backend probe） + 布局约束（layout constraint） | J13: 路径能力（PathCapability） + 功能开关（feature flags） + 遥测模式（telemetry schema） | K13: 能力缺失即关闭对应 功能开关（feature flag）；不得静默退化为HBM→DDR→SSD三级路径或不可审计CPU数据路径 | L13: 沿用V2.2；SR闭包重构后复核 | M13: =COUNTIF('SR系统设计'!$B$5:$B$42,A13)
A14: IR-01-10 | B14: SF-01 | C14: 提供可编程、可寻址、可执行的统一异构 KVCache 存储池 | D14: 支持多消费者共享、租约引用管理及故障快速回退 | E14: 租约/引用计数（Lease/RefCount） + RCU + 附加句柄（AttachHandle） + 回退契约（FallbackContract） | F14: 系统应允许多个请求、实例或并行 并行秩（rank） 安全共享同一 KV 对象，通过 附加句柄（AttachHandle）、租约（lease）、引用计数（refcount） 和消费资格控制对象何时可读、何时可迁移或释放，并合并重复远端拉取。发生超时、对象状态冲突或路径失败时，应在有界时间内切换备用副本、本地缓存或重算，既保证共享收益，又避免 陈旧视图（stale view）、资源泄漏和无限等待。 | G14: 陈旧视图故障（stale view fault）=0；重复远端拉取降低≥50%；回退（fallback）成功率=100%；回退（fallback）触发到恢复<500ms。 | H14: TM5/TM6 | I14: 附加句柄（AttachHandle） + object version + 消费者（consumer） set | J14: 租约（lease）/引用计数（refcount） transition + 回退（fallback） result | K14: 租约冲突或状态异常时阻断消费、隔离（quarantine） 并按原因码执行备用副本或重算 | L14: 沿用V2.2；SR闭包重构后复核 | M14: =COUNTIF('SR系统设计'!$B$5:$B$42,A14)
A15: IR-01-11 | B15: SF-01 | C15: 提供可编程、可寻址、可执行的统一异构 KVCache 存储池 | D15: 支持KV发布迁移一致性、多租户隔离和前后台传输QoS | E15: MVCC/RCU + ReadyBitmap + TokenBucket/WFQ + TrafficClass | F15: 系统应建立 KV 对象发布、就绪状态（ready）、版本、租约、引用、迁移和回收之间的并发一致性规则，并对 TTFT 加载、解码阶段（Decode） 关键传输、预取、写回和冷回源设置独立流量等级、带宽预算和抢占关系；同时按 tenant/security domain 隔离容量、队列和访问权限，确保后台治理和其他租户不会破坏前台 TPOT、数据正确性或服务公平性。 | G15: data corruption=0；后台干扰降低≥50%；TPOT p99回退<3%；租户间干扰<5%；越权访问=0。 | H15: TM5 | I15: object state + 流量类别（traffic class） + tenant quota | J15: atomic visibility + scheduled transfer budget | K15: 冲突对象进入等待/隔离；后台队列可暂停、排空（drain） 或限速；前台超预算直接重算 | L15: 沿用V2.2；SR闭包重构后复核 | M15: =COUNTIF('SR系统设计'!$B$5:$B$42,A15)
A16: IR-01-12 | B16: SF-01 | C16: 提供可编程、可寻址、可执行的统一异构 KVCache 存储池 | D16: 支持按路径提供KV完整性证据、访问保护及硬件故障恢复 | E16: IOMMU/MR Protection + ECC/RAS + DMA 完成/栅栏（completion/fence） + backend/hardware checksum + IntegrityPolicy | F16: 系统应在 KV 对象进入 就绪状态（ready） 或被 附加（attach） 前，根据介质和路径能力验证版本、长度、布局、DMA 完成/栅栏（completion/fence）、ECC/RAS、后端 checksum 或硬件端到端校验证据，并通过 IOMMU、MR 和安全域限制访问范围。CPU CRC不得成为所有Direct路径的统一提交前置条件；只有在受预算、可观测、可禁用的异常回退或诊断路径中允许使用。 | G16: 错误/过期 KV 被消费=0；越权访问=0；主路径CPU全量CRC=0；视图（view） revocation p99<1ms；故障注入覆盖率=100%。 | H16: TM5/TM6 | I16: path evidence + security domain + object version | J16: 就绪状态（ready）/隔离（quarantine） decision + error map | K16: 证据不足不得 就绪状态（ready）；无硬件校验时采用路径已有证据或显式回退，禁止静默CPU全量扫描 | L16: 沿用V2.2；SR闭包重构后复核 | M16: =COUNTIF('SR系统设计'!$B$5:$B$42,A16)
... A28: IR-02-12 | B28: SF-02 | C28: 提供集群级语义复用与推理 SLO 闭环的在线加速能力 | D28: 支持跨平台构建、自动化测试、性能基线及灰度发布的工程交付体系 | E28: CMake/ccache + clang-tidy + ASAN/TSAN/LSAN + Chaos Mesh + GitLab CI + Benchmark | F28: 系统应提供覆盖 CPU/NPU、vLLM/SGLang 和不同传输后端的标准构建、静态检查、单元/集成/性能/故障注入/长稳测试、制品发布、灰度放量和自动回滚流程；每次变更必须能够与冻结 基线（baseline） 做可复现对比，并以覆盖率、性能退化、泄漏、错误率和 SLO 门槛自动决定是否允许合并或发布。 | G28: 核心覆盖率>85%；MR反馈<15min；72h长稳零泄漏；故障回退（fallback）<500ms且0错误；回滚<1min。 | H28: TM6 | I28: 源代码与测试矩阵（source + test matrix） + 部署清单（deployment manifest） | J28: 质量报告（quality report） + 基准测试基线（benchmark baseline） + 发布制品（release artifact） | K28: 任一P0门禁失败阻断合并；灰度SLO异常自动回滚 | L28: 沿用V2.2；SR闭包重构后复核 | M28: =COUNTIF('SR系统设计'!$B$5:$B$42,A28)

Sheet SR系统设计
A1: SR 系统设计（独立交付功能闭包与项目贡献定位）
A2: 每条 SR 必须可独立构建、发布和验收；允许依赖其他 SR，但必须提供最小兼容基线或桩件。新增“对项目的贡献定位”列，统一说明该 SR 主要完成模块功能、优化模块性能，或同时形成两类贡献。
A4: SR ID | B4: 父 IR | C4: SF ID | D4: SR 名称 | E4: 功能实体类型 | F4: 独立交付物/版本 | G4: 直接消费者 | H4: 范围内 | I4: 范围外 | J4: 公开接口/输出契约 | K4: 主流程闭包 | L4: 失败/降级/回滚 | M4: 独立验收环境 | N4: SR 专属 KPI | O4: 最小兼容基线/桩件 | P4: 前置 SR | Q4: 阻断独立交付 | R4: 优先级 | S4: 阶段 | T4: 责任角色 | U4: 来源需求数 | V4: 来源需求 ID | W4: AR 数 | X4: SR 门禁 | Y4: 对项目的贡献定位
A5: SR23-01-01-01 | B5: IR-01-01 | C5: SF-01 | D5: 统一 KV 对象池核心组件 | E5: 组件库 | F5: kv-pool-core 静态/动态库、KV对象（KVObject）/存储区段清单（ExtentManifest） 数据模型及版本化 API 包 | G5: 层级管理器（TierManager）、连接器（Connector）、传输管理器（Transfer Manager） 与测试桩 | H5: 跨 HBM/DDR/SSD/远端介质的对象标识、存储区段（extent） 映射、分配、状态查询和基础生命周期 | I5: 冷热策略、后台迁移策略、具体硬件数据搬运 | J5: KV对象存储（KVObjectStore）、存储区段清单（ExtentManifest）、放置位置（Placement）、allocate/open/close/query 接口；错误码和对象版本兼容规则 | K5: 创建 KV对象（KVObject）→分配 存储区段（extent）→发布 放置位置（Placement）→按版本查询与释放 | L5: 后端能力缺失时使用 模拟后端（MockBackend）/主机内存后端（HostMemoryBackend）；分配失败显式返回 OOM/UNSUPPORTED，不隐式跨层搬运 | M5: 单进程 模拟后端（MockBackend） + 文件型 SSD 仿真即可完成全套功能验收，不依赖真实集群 | N5: 对象/存储区段（extent） 一致性错误=0；碎片率<5%；10万对象查询 p99<50μs；格式兼容测试通过率=100% | O5: 能力提供器（Capability Provider） v1 契约或 模拟后端（MockBackend）；不要求真实 RDMA/SSD | P5: SR23-01-09-01 | Q5: 否 | R5: P0 | S5: P0 | T5: 统一存储池组件组 | U5: =COUNTIF('追溯与覆盖'!$J$5:$J$153,A5) | V5: L3-MC-ExtentManifest-076、L3-MC-KVBlockStorageSchema-075、L3-MC-POOL-GLOBAL-001、L3-MS-KVObjectStateMachine-058、L3-MC-PageExtentAllocator-077、L3-MC-UBAllocator-049 | W5: =COUNTIF('AR开发认领'!$B$5:$B$207,A5) | X5: =IF(AND(F5<>"",G5<>"",J5<>"",L5<>"",M5<>"",N5<>"",O5<>"",U5>0,W5>=3,Q5="否"),"PASS","REVIEW") | Y5: 功能与性能协同｜完成统一 KV 对象、存储区段（extent）分配与版本查询的核心闭包；统一分层、迁移和共享的对象语义，并以低碎片、低查询时延形成全系统基座。
A6: SR23-01-01-02 | B6: IR-01-01 | C6: SF-01 | D6: HBM↔SSD 分层容量与 DDR 角色插件 | E6: 策略插件 | F6: tier-capacity-policy 插件、双水位配置、DDR 角色策略（RolePolicy） 和容量收益报告 | G6: 统一对象池、推理调度器、运维容量规划 | H6: HBM↔SSD 容量主路径、DDR warm/remote/prefetch/registered-pool 条件角色、阈值与旁路策略 | I6: 通用在线学习、硬编码三级 HBM→DDR→SSD 串行路径 | J6: 层级决策（TierDecision）、DDR角色决策（DDRRoleDecision）、水位快照（WatermarkSnapshot）、容量/回退原因（capacity/fallback reason） | K6: 读取对象热度与水位→选择 HBM/SSD 或有正收益的 DDR 角色→生成可执行分层决策 | L6: DDR 无持续正收益时退出 有效载荷（Payload） 主路径；复杂策略不优于基线时回退双水位+hysteresis | M6: 存储池核心（Pool Core） + SSD后端桩（SSDBackendStub） + 工作负载回放（workload replay） 即可独立验收 | N6: HBM有效容量提升≥30%；OOM/抢占（preemption）降低≥50%；DDR角色必须证明净收益；策略额外开销<2% | O6: POOL_CORE 与 SSD_BACKEND 的接口桩；固定模型容量画像 | P6: SR23-01-01-01、SR23-01-08-01 | Q6: 否 | R6: P0 | S6: P0 | T6: 分层容量策略组 | U6: =COUNTIF('追溯与覆盖'!$J$5:$J$153,A6) | V6: L3-MS-Tiering-038、L3-MC-HIER-STORE-002、L3-MS-DDRRolePolicy-092 | W6: =COUNTIF('AR开发认领'!$B$5:$B$207,A6) | X6: =IF(AND(F6<>"",G6<>"",J6<>"",L6<>"",M6<>"",N6<>"",O6<>"",U6>0,W6>=3,Q6="否"),"PASS","REVIEW") | Y6: 功能与性能协同｜完成 HBM↔SSD 容量策略与 DDR 条件角色模块；把“可寻址字节”转化为满足 SLO 的可服务容量，直接贡献 HBM 有效容量与单位成本竞争力。
A7: SR23-01-01-03 | B7: IR-01-01 | C7: SF-01 | D7: KV 生命周期、迁移与空间治理控制器 | E7: 组件服务 | F7: lifecycle-controller 库、迁移/压紧/淘汰状态机、管理 CLI 与回滚日志 | G7: 统一对象池、QoS 控制器和运维工具 | H7: 迁移互锁、state-aware eviction、压紧、智能搬移、成本淘汰、NUMA 亲和 | I7: 硬件原子 重映射（remap） 的强依赖、上层请求调度 | J7: LifecycleEvent、MigrationTicket、EvictionDecision、CompactionPlan 与 回滚接口（rollback API） | K7: 触发治理→冻结对象可见性→迁移/压紧→校验→原子发布→释放旧 存储区段（extent） | L7: 迁移失败回滚旧 放置位置（Placement）；高负载时暂停后台治理；硬件 重映射（remap） 不可用时使用 RCU/copy-on-migrate | M7: 存储池核心（Pool Core） + MockMover + 并发 reader/writer 测试即可独立验收 | N7: 错误释放/活跃对象误淘汰=0；迁移 TPOT 抖动<5%；压紧可回滚；治理后碎片率<5% | O7: POOL_CORE、CONSISTENCY_SERVICE 与 MockMover | P7: SR23-01-01-01、SR23-01-11-01 | Q7: 否 | R7: P0 | S7: P0 | T7: 生命周期与空间治理组 | U7: =COUNTIF('追溯与覆盖'!$J$5:$J$153,A7) | V7: L3-MS-MigrationInterlock-062、L3-MS-StateAwareEviction-082、L3-MC-CompactionEngine-056、L3-MC-IntelligentMigration-057、L3-MS-CostEviction-039、L3-MC-POOL-ALLOC-005 | W7: =COUNTIF('AR开发认领'!$B$5:$B$207,A7) | X7: =IF(AND(F7<>"",G7<>"",J7<>"",L7<>"",M7<>"",N7<>"",O7<>"",U7>0,W7>=3,Q7="否"),"PASS","REVIEW") | Y7: 功能与性能协同｜完成对象状态、迁移、回收与空间治理闭包；通过有界迁移和碎片治理降低 OOM、抢占（preemption）及长稳风险。
A8: SR23-01-02-01 | B8: IR-01-02 | C8: SF-01 | D8: 跨框架布局与批量传输描述编译器 | E8: 组件库 | F8: descriptor-compiler 库、vLLM/SGLang 布局（layout） 适配器（adapter）、黄金布局用例（golden layout cases） | G8: 异步传输 有向无环图（DAG）、RDMA/SSD/UBMEM 提供器（Provider） | H8: 存储区段清单（ExtentManifest）→SG/segment 描述符（descriptor）、布局协商、显式 转换（transform）、部分前缀（partial prefix） | I8: 实际硬件传输执行、完整推理调度 | J8: compile(manifest, targetCapability)→批量描述符（BulkDescriptor）/布局转换计划（LayoutTransformPlan） | K8: 解析逻辑 块（block）/page→匹配目标 能力（capability）→合并片段→输出批量描述符 | L8: 布局不兼容时返回显式 转换（transform） 或 RECOMPUTE；禁止隐式错误 附加（attach） | M8: 两种框架 布局测试夹具（layout fixture） + 模拟提供器（MockProvider） 即可独立验收 | N8: 描述符（descriptor） 数下降≥50%；CPU提交时延（CPU submit time）下降≥40%；布局协商错误=0；黄金用例（golden case） 100%通过 | O8: POOL_CORE、CAP_ROUTER 契约或 测试夹具（fixture） | P8: SR23-01-01-01、SR23-01-09-01 | Q8: 否 | R8: P0 | S8: P0 | T8: 布局与描述编译组 | U8: =COUNTIF('追溯与覆盖'!$J$5:$J$153,A8) | V8: L3-SE-DescriptorFromManifest-079、L2-KV-PartialAttachPlan-038、L2-OL-BulkDescriptor-025、L2-OL-LayoutNegotiation-024、L3-MC-LayoutTransformPlan-078 | W8: =COUNTIF('AR开发认领'!$B$5:$B$207,A8) | X8: =IF(AND(F8<>"",G8<>"",J8<>"",L8<>"",M8<>"",N8<>"",O8<>"",U8>0,W8>=3,Q8="否"),"PASS","REVIEW") | Y8: 功能与性能协同｜完成 vLLM/SGLang 布局到批量传输描述符的编译闭包；减少逐块提交、小 I/O 放大和 CPU 提交开销，使跨框架数据路径可复用。
A9: SR23-01-03-01 | B9: IR-01-03 | C9: SF-01 | D9: 查询计划（QueryPlan） 与多副本成本决策引擎 | E9: 组件服务 | F9: queryplan-engine 库、策略引擎（PolicyEngine）/放置解析器（PlacementResolver）、影子/标准判定（shadow/oracle） 对账工具 | G9: 推理 准入控制（Admission）、缓存感知路由器（Cache-aware Router）、预取与回填策略 | H9: 加载与重算（load-vs-recompute）、候选副本排序、视图与复制对比（View-vs-Copy）、层级旁路（Tier bypass） 与 回退链（fallback chain） | I9: 目录存储实现、底层 描述符（descriptor） 执行 | J9: plan(KV访问意图（KVAccessIntent）, candidates, 遥测数据（telemetry）)→排序后的查询计划（ranked QueryPlan） + 决策原因（decision reason） | K9: 读取请求 截止时限（deadline）/重算收益/路径成本→排序候选→选择消费动作和回退链 | L9: 成本估计不可信或超预算时选择本地副本/部分重算（partial recompute）/重算（recompute） | M9: 录制的 候选项（candidate）/遥测数据（telemetry） 测试夹具（fixture） + 离线 oracle 即可独立验收 | N9: 策略 p99<5μs；路径选择准确率≥90%；成本预测误差<20%；错误 加载（Load）<1% | O9: PATH_ROUTER、DIRECTORY_FASTPATH 接口桩和固定 工作负载（workload） | P9: SR23-01-05-01、SR23-02-05-02 | Q9: 否 | R9: P0 | S9: P0 | T9: 语义策略与成本模型组 | U9: =COUNTIF('追溯与覆盖'!$J$5:$J$153,A9) | V9: L3-SE-PlacementResolver-061、L3-SE-PolicyEngine-032、L3-SE-QueryPlanFastPath-072、L3-SE-TierBypassPolicy-091、L3-SE-MultiReplicaResolver-089、L3-SE-ViewCopyCostModel-034 | W9: =COUNTIF('AR开发认领'!$B$5:$B$207,A9) | X9: =IF(AND(F9<>"",G9<>"",J9<>"",L9<>"",M9<>"",N9<>"",O9<>"",U9>0,W9>=3,Q9="否"),"PASS","REVIEW") | Y9: 模块性能优化｜以正价值为目标，在微秒级比较直接访问（View）、加载（Load）与重算（Recompute）；减少负收益命中和决策后悔，直接优化 TTFT、跨节点流量与单位事务成本。
A10: SR23-01-03-02 | B10: IR-01-03 | C10: SF-01 | D10: 统一传输意图与粒度分发组件 | E10: 组件库 | F10: transfer-intent API、统一 描述符（descriptor） 模式（schema）、metadata/有效载荷（payload） 粒度分发器 | G10: 查询计划（QueryPlan）、异步 有向无环图（DAG） 与所有 后端提供器（Backend Provider） | H10: 跨框架传输意图归一化、统一语义引擎、元数据与 有效载荷（Payload） 分流 | I10: 路径成本选择、实际硬件执行 | J10: TransferIntent、UnifiedDescriptor、GranularityClass、ProviderRequest | K10: 接收 查询计划（QueryPlan）→规范化传输意图→按对象粒度路由到 描述符（descriptor）/provider | L10: 提供器（Provider） 不支持时返回 UNSUPPORTED 并交由 查询计划（QueryPlan） 切副本或重算 | M10: 模式一致性（Schema conformance） + 三种 模拟提供器（MockProvider） 即可独立验收 | N10: 跨框架语义一致性测试100%；错误 提供器（Provider） 路由=0；单次归一化 p99<3μs | O10: CONNECTOR_PROTOCOL 与 CAP_ROUTER 契约 | P10: SR23-02-01-01、SR23-01-09-01 | Q10: 否 | R10: P0 | S10: P0 | T10: 统一传输语义组 | U10: =COUNTIF('追溯与覆盖'!$J$5:$J$153,A10) | V10: L3-SE-UnifiedDescriptor-018、L3-TRANS-SEM-ENGINE-001、L3-SE-GranularityDispatch-033 | W10: =COUNTIF('AR开发认领'!$B$5:$B$207,A10) | X10: =IF(AND(F10<>"",G10<>"",J10<>"",L10<>"",M10<>"",N10<>"",O10<>"",U10>0,W10>=3,Q10="否"),"PASS","REVIEW") | Y10: 模块功能闭包｜统一框架层传输意图、对象粒度和批量粒度的分发契约；隔离上层语义与具体后端，为多 Provider 兼容、替换和独立交付提供稳定接口。
A11: SR23-01-04-01 | B11: IR-01-04 | C11: SF-01 | D11: 异步传输 有向无环图（DAG） 与流水加载执行器 | E11: 组件服务 | F11: async-transfer-dag 库、传输票据（TransferTicket）、取消/超时/部分完成控制器 | G11: P/D 交接、KV 加载流水线、热点复制与 提供器（Provider） | H11: 任务依赖、page/layer 流水、复制/预取、P2P 路由、并发额度和取消 | I11: 硬件多播专用实现、上层负载预测 | J11: submit(查询计划（QueryPlan）, descriptors)→TransferTicket/completion/fence/per-target result | K11: 构造 有向无环图（DAG）→按依赖与队列提交→逐 page/layer 完成→发布 就绪状态（ready） | L11: 截止时限（deadline） 到期取消未提交任务；部分目标失败隔离重试；主路径失败切备用 提供器（Provider） | M11: 描述符编译器（DescriptorCompiler） + 模拟提供器（MockProvider） + 模拟时钟（fake clock） 即可独立验收 | N11: 计算/传输重叠≥60%；取消资源泄漏=0；部分完成状态一致；预填充/解码交接（P/D handoff） p99降低≥20% | O11: DESCRIPTOR_COMPILER、TRANSFER_INTENT 及 模拟提供器（MockProvider） | P11: SR23-01-02-01、SR23-01-03-02 | Q11: 否 | R11: P1 | S11: P1 | T11: 异步传输编排组 | U11: =COUNTIF('追溯与覆盖'!$J$5:$J$153,A11) | V11: L3-MS-HotReplication-040、L3-MS-StateAwarePrefetch-081、L3-C2C-POOL-SCHED-002、L3-LMC-PRFCH-ENGINE-001、L3-UB-TOPO-ROUTE-001 | W11: =COUNTIF('AR开发认领'!$B$5:$B$207,A11) | X11: =IF(AND(F11<>"",G11<>"",J11<>"",L11<>"",M11<>"",N11<>"",O11<>"",U11>0,W11>=3,Q11="否"),"PASS","REVIEW") | Y11: 功能与性能协同｜完成可取消、可回退的异步传输 DAG 与流水加载闭包；提高计算—传输重叠并抑制串行等待，使局部带宽转化为端到端 TTFT 收益。
A12: SR23-01-04-02 | B12: IR-01-04 | C12: SF-01 | D12: 一对多共享与可选多播 提供器（Provider） | E12: 可选插件 | F12: fanout-provider 插件、软件 staging 基线、硬件 multicast 功能开关（feature flag） | G12: 热点前缀复制、共享 附加（Attach） 与异步 有向无环图（DAG） | H12: 1→N 分发、慢消费者隔离、per-target 结果和软件/硬件 扇出分发（fanout） | I12: 全局热度预测、默认依赖硬件 multicast | J12: 扇出请求（FanoutRequest）、目标结果（TargetResult）、多播能力（MulticastCapability） | K12: 一次读取源对象→按目标能力选择 staging 或 multicast→逐目标完成 | L12: 硬件多播无收益或不可用时回退软件 扇出分发（fanout）；单目标失败不阻塞其他目标 | M12: 1源+2/4/8 模拟消费者（MockConsumer） 即可独立验收 | N12: 重复远端拉取下降≥50%；错误共享/租约泄漏=0；源端带宽增长显著低于 O(N) | O12: ASYNC_DAG 与 SHARED_ATTACH | P12: SR23-01-04-01、SR23-01-10-01 | Q12: 否 | R12: P3 | S12: P3 | T12: 共享分发插件组 | U12: =COUNTIF('追溯与覆盖'!$J$5:$J$153,A12) | V12: L3-TRANS-MUL-ENGINE-003、L4-RDMA-MUL-FABRIC-002 | W12: =COUNTIF('AR开发认领'!$B$5:$B$207,A12) | X12: =IF(AND(F12<>"",G12<>"",J12<>"",L12<>"",M12<>"",N12<>"",O12<>"",U12>0,W12>=3,Q12="否"),"PASS","REVIEW") | Y12: 模块性能优化｜在真实一对多复用达到交叉点时，通过软件扇出或可选多播减少重复远端字节和源端带宽；未达净收益时保持关闭，不成为主路径依赖。
A13: SR23-01-05-01 | B13: IR-01-05 | C13: SF-01 | D13: 路径质量探测与动态路由组件 | E13: 组件服务 | F13: path-quality-monitor、拓扑快照、动态路径评分器和故障切换控制器 | G13: 查询计划（QueryPlan）、连接器路由器（Connector Router）、后端注册表（Backend Registry） | H13: 路径带宽/时延/水位探测、拓扑感知、动态质量评分、故障切换 | I13: 具体 提供器（Provider） 传输执行、在线学习 | J13: 路径健康快照（PathHealthSnapshot）、路由候选项（RouteCandidate）、selectPath(size,SLO) | K13: 周期探测→更新路径健康快照→按大小/SLO/拥塞评分选路 | L13: 质量噪声过大时使用静态白名单；探测失败不阻塞数据面；故障路径立即摘除 | M13: 三条模拟路径与故障注入即可独立验收 | N13: 路径选择准确率≥90%；切换<200ms；探测开销<0.5%带宽；无效路径选择=0 | O13: CAP_ROUTER 与 提供器（Provider） 模拟器 | P13: SR23-01-09-01 | Q13: 否 | R13: P1 | S13: P1 | T13: 拓扑与路径质量组 | U13: =COUNTIF('追溯与覆盖'!$J$5:$J$153,A13) | V13: L2-CONN-TOPO-ROUTE-002、L2-CONN-WatermarkQuery-032、L3-TRANS-TOPO-SENSE-004 | W13: =COUNTIF('AR开发认领'!$B$5:$B$207,A13) | X13: =IF(AND(F13<>"",G13<>"",J13<>"",L13<>"",M13<>"",N13<>"",O13<>"",U13>0,W13>=3,Q13="否"),"PASS","REVIEW") | Y13: 功能与性能协同｜完成路径质量探测、退化识别与动态路由闭包；避免按静态能力或理论峰值选错路径，降低尾延迟、回退和故障恢复成本。
A14: SR23-01-06-01 | B14: IR-01-06 | C14: SF-01 | D14: 跨节点 RDMA 零拷贝 提供器（Provider） | E14: 后端插件 | F14: rdma-provider、注册内存池（RegisteredPool）、远端存储区段句柄（RemoteExtentHandle）、硬件/软件回归包 | G14: 能力（Capability） 路由器（Router）、异步有向无环图（Async DAG） 与远端副本加载 | H14: MR 注册池、远端句柄、安全寻址、NPU/HBM/DDR 零拷贝传输 | I14: 全局路径决策、CPU staging 作为默认路径 | J14: ProviderCapability、register/transfer/cancel/queryCompletion | K14: 复用注册区→解析远端句柄→提交 RDMA→CQ/fence→发布完成证据 | L14: GPUDirect/NPU Direct 不支持时显式返回 STAGED_ONLY；由上层决定是否限流使用 | M14: loopback/模拟器（simulator） 可完成接口与错误测试；真实硬件用于性能门禁 | N14: 有效带宽≥线速80%；CPU 有效载荷（Payload） 复制（copy）=0；提交开销<50μs；越界访问=0 | O14: CAP_ROUTER、INTEGRITY_EVIDENCE 和 rdma 模拟器（simulator） | P14: SR23-01-09-01、SR23-01-12-01 | Q14: 否 | R14: P0 | S14: P0 | T14: RDMA 后端组 | U14: =COUNTIF('追溯与覆盖'!$J$5:$J$153,A14) | V14: L4-OL-RegisteredPool-053、L4-RDMA-RemoteExtentHandle-071、L4-RDMA-P2P-NPU-001 | W14: =COUNTIF('AR开发认领'!$B$5:$B$207,A14) | X14: =IF(AND(F14<>"",G14<>"",J14<>"",L14<>"",M14<>"",N14<>"",O14<>"",U14>0,W14>=3,Q14="否"),"PASS","REVIEW") | Y14: 模块性能优化｜交付跨节点 RDMA 零拷贝 Provider，在可审计 主机有效载荷触碰（Host Payload Touch） 边界下提高热路径有效带宽并降低 CPU 参与，形成目标硬件高速路径竞争力。
A15: SR23-01-07-01 | B15: IR-01-07 | C15: SF-01 | D15: UBMEM/C2C 直接视图（Direct View） 安全访问 提供器（Provider） | E15: 后端插件 | F15: direct-view-provider、DirectViewGuard、租约（lease）/撤销（revoke） 与 复制到 HBM（copy-to-HBM） 回填适配 | G15: 共享 附加（Attach）、视图与复制对比（View-vs-Copy） 策略与统一池 | H15: 合格 metadata/KV区间（KV span） 的只读 视图（view）、回填、访问保护与失效 | I15: 默认将 decode-active KV 远端直访、跨租户写共享 | J15: ViewHandle、acquire/撤销（revoke）、AccessEvidence、copyToHBM | K15: 验证对象类型/版本/租约→创建只读 视图（view）→消费→撤销（revoke） | L15: 不在安全区或远端 停顿（stall） 超阈值时 复制到 HBM（copy-to-HBM）；失效后禁止继续访问 | M15: UBMEM 模拟器（simulator） + page-fault/撤销（revoke） 注入即可独立验收 | N15: 陈旧（stale）/越界 视图（view）=0；撤销（revoke） p99<1ms；安全区 TPOT p99回退<3%；主机有效载荷访问（Host Payload touch）=0 | O15: CAP_ROUTER、INTEGRITY_EVIDENCE、SECURE_LIFECYCLE | P15: SR23-01-09-01、SR23-01-12-01、SR23-01-12-02 | Q15: 否 | R15: P0 | S15: P0 | T15: 统一内存访问组 | U15: =COUNTIF('追溯与覆盖'!$J$5:$J$153,A15) | V15: L4-UB-DirectViewGuard-072、L3-MS-UBC2CTier-055、L4-C2C-UNIFY-POOL-001、L4-UB-C2C-UNIFY-002、L4-UB-P2P-FABRIC-003 | W15: =COUNTIF('AR开发认领'!$B$5:$B$207,A15) | X15: =IF(AND(F15<>"",G15<>"",J15<>"",L15<>"",M15<>"",N15<>"",O15<>"",U15>0,W15>=3,Q15="否"),"PASS","REVIEW") | Y15: 功能与性能协同｜完成 UBMEM/C2C 直接访问、租约保护和安全回退闭包；仅在正收益对象上减少复制，同时防止远端随机访问恶化 TPOT。
A16: SR23-01-08-01 | B16: IR-01-08 | C16: SF-01 | D16: HBM↔SSD/对象存储（SSD/Object） 容量后端 | E16: 后端插件 | F16: ssd-object-provider、持久存储区段句柄（PersistentExtentHandle）、Direct/low-host I/O 能力表 | G16: 统一池、分层容量策略和加载流水线 | H16: SSD/对象存储（SSD/Object） 存储区段（extent） 持久句柄、批量读写、Direct/low-host 路径、完成与可见性 | I16: CPU 编解码器（codec）/全量 CRC 作为默认回退 | J16: 持久存储区段句柄（PersistentExtentHandle）、read/write/restore、存储能力（StorageCapability） | K16: 解析持久 存储区段（extent）→批量提交 I/O→完成/完整性证据→就绪状态（ready） | L16: Direct Storage 不可用时返回 分阶段暂存（staged） 能力与明确 Host 预算，不伪装直达 | M16: 文件后端可做功能验收；NVMe/对象存储用于性能门禁 | N16: 顺序带宽≥设备峰值80%；错误/半写消费=0；主路径 主机有效载荷访问（Host Payload touch）=0 | O16: CAP_ROUTER、INTEGRITY_EVIDENCE 与文件型 提供器（Provider） 桩 | P16: SR23-01-09-01、SR23-01-12-01 | Q16: 否 | R16: P0 | S16: P0 子集 + P1 完整 | T16: SSD/对象存储（SSD/Object） 后端组 | U16: =COUNTIF('追溯与覆盖'!$J$5:$J$153,A16) | V16: L4-MC-HIER-STORE-001、L4-MC-PersistentExtentHandle-070 | W16: =COUNTIF('AR开发认领'!$B$5:$B$207,A16) | X16: =IF(AND(F16<>"",G16<>"",J16<>"",L16<>"",M16<>"",N16<>"",O16<>"",U16>0,W16>=3,Q16="否"),"PASS","REVIEW") | Y16: 功能与性能协同｜完成 HBM↔SSD/Object 容量后端及完成/回退契约；把低成本介质纳入可认证真实路径，提升可服务容量并避免隐式 CPU/DDR 中转。
A17: SR23-01-08-02 | B17: IR-01-08 | C17: SF-01 | D17: DPU/硬件 编解码器（Codec） 条件卸载插件包 | E17: 条件插件 | F17: offload-provider 插件接口、DPU/编解码器（codec） 功能开关（feature flag）、不支持（Not Supported）/Go 报告模板 | G17: 能力（Capability） 路由器（Router） 与 SSD/RDMA 提供器（Provider） | H17: 硬件压缩、解压、CQ/route 卸载的能力声明、A/B 和无损旁路 | I17: CPU 压缩/解压、CPU 全量 CRC、无硬件时占用默认人力基线 | J17: OffloadCapability、encode/decode/submitCQ、bypass | K17: 探测真实硬件能力→仅对正收益对象启用→上报收益和 主机访问（Host touch） | L17: 硬件不可用/无净收益/故障时旁路为 原始/直接（raw/direct）；禁止切 CPU 编解码器（codec） | M17: 无硬件时完成 不支持（Not Supported） 契约验收；有硬件时执行 A/B | N17: 有硬件时 Host CPU下降≥30%且端到端净收益为正；故障旁路成功率100% | O17: CAP_ROUTER 与 SSD_BACKEND/RDMA_PROVIDER 接口 | P17: SR23-01-09-01、SR23-01-08-01、SR23-01-06-01 | Q17: 否 | R17: P3 | S17: P3 | T17: 条件硬件卸载组 | U17: =COUNTIF('追溯与覆盖'!$J$5:$J$153,A17) | V17: L4-MC-HIER-STORE-002、L4-MC-HIER-STORE-003、L4-NET-OFFLOAD-DPU-001 | W17: =COUNTIF('AR开发认领'!$B$5:$B$207,A17) | X17: =IF(AND(F17<>"",G17<>"",J17<>"",L17<>"",M17<>"",N17<>"",O17<>"",U17>0,W17>=3,Q17="否"),"PASS","REVIEW") | Y17: 模块性能优化｜以功能开关交付 DPU/硬件编解码条件卸载；只有相对原始直达路径产生端到端净收益时启用，避免把可选硬件固化为项目成立前提。
A18: SR23-01-09-01 | B18: IR-01-09 | C18: SF-01 | D18: 统一 能力（Capability） 注册表（Registry） 与 互联网络路由器（Fabric Router） | E18: 平台组件 | F18: capability-registry、后端提供器（Backend Provider） SDK、互联路由器（FabricRouter） 与能力快照 | G18: Pool、查询计划（QueryPlan）、连接器（Connector）、所有传输 提供器（Provider） | H18: UB/URMA/RDMA/C2C/SSD 能力抽象、提供器（Provider） 注册、主机访问（Host touch） 真值、布局约束与选路 | I18: 业务负载决策、具体 提供器（Provider） 内部实现 | J18: 提供器（Provider） SDK、能力矩阵（CapabilityMatrix）、selectProvider、功能开关（feature flags） | K18: 探测/注册 提供器（Provider）→形成版本化能力矩阵→按请求约束选择可用 提供器（Provider） | L18: 能力缺失时关闭 功能开关（feature flag）；分阶段暂存（staged） 例外显式可见、可限流、可禁用 | M18: 三类 模拟提供器（MockProvider） 即可独立完成 SDK 和路由验收 | N18: 能力字段覆盖率100%；错误路由=0；互联网络路由器（Fabric Router） p99<3μs；所有 分阶段暂存（staged） 路径可审计 | O18: 提供器（Provider） SDK 自带 模拟提供器（MockProvider），无外部前置 | Q18: 否 | R18: P0 | S18: P0 | T18: 传输底座平台组 | U18: =COUNTIF('追溯与覆盖'!$J$5:$J$153,A18) | V18: L3-TRANS-CAP-API-002、L4-FABRIC-ROUTER-001、L4-HW-HostPayloadTouchBudget-076、L4-HW-SemCapTable-050、L4-HW-StorageLayoutCapability-067、L4-HW-AddrTrans-051、L4-HW-NICSpecConstraint-075 | W18: =COUNTIF('AR开发认领'!$B$5:$B$207,A18) | X18: =IF(AND(F18<>"",G18<>"",J18<>"",L18<>"",M18<>"",N18<>"",O18<>"",U18>0,W18>=3,Q18="否"),"PASS","REVIEW") | Y18: 模块功能闭包｜建立统一能力注册表（Capability Registry）与互连路由器（Fabric Router）契约；把 UB/URMA/RDMA/C2C/SSD Provider 组织为可发现、可替换、可审计的开放数据平面。
A19: SR23-01-10-01 | B19: IR-01-10 | C19: SF-01 | D19: 共享 附加（Attach）、租约引用与快速回退组件 | E19: 组件库 | F19: shared-attach 库、AttachHandle/Lease/RefCount、回退契约（FallbackContract） 与 故障用例（fault cases） | G19: vLLM/SGLang 连接器（Connector）、目录（Directory）、Fanout 与 直接视图（Direct View） | H19: 多 消费者（consumer） 附加（attach）、租约、引用、失败原因码、defrag pause 和批量共享 | I19: 对象物理迁移实现、全局副本目录 | J19: 附加句柄（AttachHandle）、LeaseToken、获取/释放（acquire/release）、FallbackReason | K19: 消费资格确认→获取租约→返回 附加句柄（AttachHandle）→释放/续租 | L19: 加载/状态失败切备用副本或重算；失效租约立即阻断消费 | M19: 连接器（Connector） 测试夹具（fixture） + MockObjectStore 即可独立验收 | N19: 陈旧视图故障（stale view fault）=0；回退（fallback）成功率100%；重复远端拉取下降≥50%；租约泄漏=0 | O19: CONNECTOR_PROTOCOL、CONSISTENCY_SERVICE、INTEGRITY_EVIDENCE | P19: SR23-02-01-01、SR23-01-11-01、SR23-01-12-01 | Q19: 否 | R19: P0 | S19: P0 | T19: 共享访问与回退组 | U19: =COUNTIF('追溯与覆盖'!$J$5:$J$153,A19) | V19: L2-FT-FallbackContract-029、L2-KV-AttachHandle-034、L2-KV-StateErrorCode-037、L2-MM-ViewLease-028、L2-CONN-DefragPause-031、L2-MM-MultiConsumer-027 | W19: =COUNTIF('AR开发认领'!$B$5:$B$207,A19) | X19: =IF(AND(F19<>"",G19<>"",J19<>"",L19<>"",M19<>"",N19<>"",O19<>"",U19>0,W19>=3,Q19="否"),"PASS","REVIEW") | Y19: 模块功能闭包｜完成共享接入（Attach）、租约引用、撤销和快速回退闭包；使多消费者能够安全复用同一 KV，并保证失败时不消费错误或过期状态。
A20: SR23-01-11-01 | B20: IR-01-11 | C20: SF-01 | D20: KV 发布、可见性与迁移一致性服务 | E20: 组件服务 | F20: consistency-service、PublishCommitLog、ReadyBitmap、RCU 租约（lease） 与 隔离（quarantine） | G20: Pool、目录（Directory）、附加（Attach）、Lifecycle Controller | H20: 版本发布、就绪状态（ready） 可见性、所有权/引用回收、迁移互锁、异常副本隔离 | I20: 租户配额与网络流量 QoS | J20: publish/commit/abort、ReadyEvidence、OwnershipToken、隔离（quarantine） | K20: 写入 存储区段（extent）→完整性/完成证据→原子发布版本→对消费者可见 | L20: 发布中断回滚 提交日志（commit log）；证据不足保持 NOT_READY；异常副本 隔离（quarantine） | M20: 内存状态机 + 并发/故障注入即可独立验收 | N20: 错误/半写对象可见=0；释放后使用（use-after-free）=0；发布恢复成功率100%；迁移抖动<5% | O20: POOL_CORE 与 INTEGRITY_EVIDENCE | P20: SR23-01-01-01、SR23-01-12-01 | Q20: 否 | R20: P0 | S20: P0 | T20: 一致性与生命周期组 | U20: =COUNTIF('追溯与覆盖'!$J$5:$J$153,A20) | V20: L3-CO-AttachDetachLease-063、L3-CO-KVOwnershipGC-080、L3-CO-PublishCommitLog-065、L3-CO-RefCountLifecycle-086、L3-CO-VersionPublish-043、L3-CO-VisibilityReadyBitmap-064、L3-CO-MigrationRCULock-090、L3-CO-ReplicaQuarantine-068 | W20: =COUNTIF('AR开发认领'!$B$5:$B$207,A20) | X20: =IF(AND(F20<>"",G20<>"",J20<>"",L20<>"",M20<>"",N20<>"",O20<>"",U20>0,W20>=3,Q20="否"),"PASS","REVIEW") | Y20: 模块功能闭包｜完成 KV 发布、可见性、可消费就绪（Ready）与迁移一致性状态机；以“先证据、后消费”保证错误/半写/过期 KV 消费为零。
A21: SR23-01-11-02 | B21: IR-01-11 | C21: SF-01 | D21: 多租户隔离与前后台传输 QoS 控制器 | E21: 组件服务 | F21: tenant-qos-controller、TrafficClass/TokenBucket/WFQ 配置和混压安全包络 | G21: 异步有向无环图（Async DAG）、Lifecycle Controller 与平台运维 | H21: 租户池隔离、前台/后台语义队列、迁移限速、硬件 TC 映射 | I21: 业务计费、完整集群调度 | J21: TrafficClass、TransferBudget、TenantQuota、pause/排空（drain） | K21: 分类请求→分配令牌/队列→执行→按 TPOT/水位反馈调节 | L21: 硬件 TC 不可用时使用软件队列；超预算暂停后台任务；前台超时回退重算 | M21: 软件队列模拟器 + 混压 工作负载（workload） 即可独立验收 | N21: TPOT p99回退<3%；租户间干扰<5%；越权访问=0；后台干扰降低≥50% | O21: CONSISTENCY_SERVICE、CAP_ROUTER 与 MockQueue | P21: SR23-01-11-01、SR23-01-09-01 | Q21: 否 | R21: P0 | S21: P0 | T21: 隔离与 QoS 组 | U21: =COUNTIF('追溯与覆盖'!$J$5:$J$153,A21) | V21: L3-QO-SemanticQoS-045、L3-SC-PoolIsolation-048、L4-QO-MigrationQoS-064、L4-QO-StateAwareTrafficClass-068、L4-QO-TrafficClass-056 | W21: =COUNTIF('AR开发认领'!$B$5:$B$207,A21) | X21: =IF(AND(F21<>"",G21<>"",J21<>"",L21<>"",M21<>"",N21<>"",O21<>"",U21>0,W21>=3,Q21="否"),"PASS","REVIEW") | Y21: 模块性能优化｜通过多租户隔离和前后台传输 QoS 控制共享带宽与队列干扰；在提升 TTFT/容量的同时守住 TPOT 尾延迟与租户公平性。
A22: SR23-01-12-01 | B22: IR-01-12 | C22: SF-01 | D22: 按路径完整性证据与 RAS 故障映射组件 | E22: 平台组件 | F22: integrity-evidence SDK、完成/栅栏（Completion/Fence） 证据模型、RAS/ErrorMap 与 故障测试套件（fault suite） | G22: 所有 提供器（Provider）、Consistency Service 与 附加（Attach） | H22: 完成→fence→完整性→就绪状态（ready） 证据链、差异化后端校验、RAS 映射 | I22: CPU 全量 CRC 作为主路径前置 | J22: IntegrityEvidence、CompletionEvidence、ErrorMap、canPublishReady | K22: 收集路径原生证据→验证对象版本/范围→生成可发布结论 | L22: 证据不足不得 就绪状态（ready）；无硬件校验时使用后端已有证据或回退重算 | M22: FakeProvider + 半写/ECC/超时/乱序注入即可独立验收 | N22: 错误/过期 KV 被消费=0；故障注入覆盖率100%；主路径 CPU 全量 CRC=0 | O22: CAP_ROUTER 提供器（Provider） SDK 与 FakeProvider | P22: SR23-01-09-01 | Q22: 否 | R22: P0 | S22: P0 | T22: 完整性与 RAS 组 | U22: =COUNTIF('追溯与覆盖'!$J$5:$J$153,A22) | V22: L4-CO-ExtentVisibilityFence-066、L4-CO-FencePrimitive-052、L4-FT-PathIntegrityPolicy-077、L4-FT-RASErrorMap-061、L4-FT-ReplicaIntegrityCheck-069 | W22: =COUNTIF('AR开发认领'!$B$5:$B$207,A22) | X22: =IF(AND(F22<>"",G22<>"",J22<>"",L22<>"",M22<>"",N22<>"",O22<>"",U22>0,W22>=3,Q22="否"),"PASS","REVIEW") | Y22: 模块功能闭包｜按实际路径形成完整性证据、RAS 故障映射和阻断规则；为原厂系统问题归因、错误消费防护和跨版本认证提供可审计依据。
A23: SR23-01-12-02 | B23: IR-01-12 | C23: SF-01 | D23: 安全访问、资源下线与地址切换组件 | E23: 平台组件 | F23: secure-lifecycle 库、ViewProtection、排空/静默（drain/quiesce）、secure release 与 重映射（remap） 适配器（adapter） | G23: 直接视图（Direct View）、Pool、Lifecycle Controller 与租户管理 | H23: 访问保护、租户边界、后端下线、地址切换、安全释放、可选 page migration | I23: 强制依赖硬件 atomic 重映射（remap）、跨租户共享写 | J23: AccessPolicy、排空/静默（drain/quiesce）、secureRelease、重映射（remap）/rollback | K23: 撤销新访问→等待/迁移存量 租约（lease）→安全清理→释放或切换地址 | L23: 硬件 重映射（remap） 不可用时使用 RCU+copy-on-migrate；无法安全下线时保持隔离 | M23: IOMMU/MR 模拟器 + 并发 租约（lease） 测试即可独立验收 | N23: 越权访问=0；安全释放后残留读取=0；视图（view） 撤销（revoke） p99<1ms；失败可回滚 | O23: CONSISTENCY_SERVICE 与 INTEGRITY_EVIDENCE | P23: SR23-01-11-01、SR23-01-12-01 | Q23: 否 | R23: P0 | S23: P0 | T23: 安全访问与资源治理组 | U23: =COUNTIF('追溯与覆盖'!$J$5:$J$153,A23) | V23: L1-SC-TenantIsolation-017、L4-SC-ViewProtection-062、L4-CO-DrainAndQuiesce-073、L4-CO-AtomicRemapPrimitive-065、L4-SC-SecureExtentRelease-074、L4-CO-PageMigration-063 | W23: =COUNTIF('AR开发认领'!$B$5:$B$207,A23) | X23: =IF(AND(F23<>"",G23<>"",J23<>"",L23<>"",M23<>"",N23<>"",O23<>"",U23>0,W23>=3,Q23="否"),"PASS","REVIEW") | Y23: 模块功能闭包｜完成安全访问、资源下线、地址切换与回滚闭包；保证迁移、故障和升级过程中无越权、悬空引用或不可恢复状态。
A24: SR23-02-01-01 | B24: IR-02-01 | C24: SF-02 | D24: vLLM/SGLang 统一 KV连接器（KVConnector） 协议与插件 SDK | E24: 协议与 SDK | F24: KV连接器（KVConnector） 协议（Protocol）、C++/Python SDK、gRPC/Protobuf IDL、符合性测试套件（conformance suite） | G24: vLLM、SGLang、查询计划（QueryPlan）、目录（Directory） 和 后端（Backend） 插件 | H24: KVAccessIntent/QueryPlan/AttachHandle、put/get/prefetch/evict/status、buffer contract 与语义身份 | I24: 具体目录/存储/传输实现 | J24: 版本化 SDK/IDL、同步/异步语义、错误码、超时、重试与兼容规则 | K24: 框架生成 意图（Intent）→调用 连接器（Connector）→接收 查询计划（QueryPlan）/附加句柄（AttachHandle）→消费或回退 | L24: 插件缺失或版本不兼容时禁用统一池并回到框架原生 cache/重算（recompute） | M24: Reference 连接器（Connector） + 两个框架 适配器（adapter） mock 即可独立验收 | N24: 符合性（conformance）通过率100%；接口调用 p99<5μs；新后端接入工期降低≥50% | O24: Reference 连接器（Connector） 自包含，无外部前置 | Q24: 否 | R24: P0 | S24: P0 | T24: 连接器（Connector） 协议与框架接入组 | U24: =COUNTIF('追溯与覆盖'!$J$5:$J$153,A24) | V24: L2-CONN-API-STD-001、L2-CONN-BufferContract-040、L2-CONN-CostAwareReturn-039、L2-KV-PublishCommit-033、L2-KV-SemanticIdentity-036 | W24: =COUNTIF('AR开发认领'!$B$5:$B$207,A24) | X24: =IF(AND(F24<>"",G24<>"",J24<>"",L24<>"",M24<>"",N24<>"",O24<>"",U24>0,W24>=3,Q24="否"),"PASS","REVIEW") | Y24: 模块功能闭包｜交付 vLLM/SGLang 统一连接器（KVConnector）协议与插件 SDK；降低框架和后端接入成本，使开源 Provider 可兼容复用且由本项目承担一致性责任。
A25: SR23-02-02-01 | B25: IR-02-02 | C25: SF-02 | D25: 前缀预算（Prefix Budget）、加载与重算（load-vs-recompute） 与水位准入组件 | E25: 框架插件 | F25: admission-engine 插件、前缀预算（PrefixBudget）/水位准入（WatermarkAdmission） 与 影子决策（shadow decision） 日志 | G25: vLLM/SGLang 调度器（Scheduler） 和 查询计划（QueryPlan） | H25: 前缀决策预算、加载收益判断、级联水位反压与 partial/重算（recompute） | I25: 实例级 cache-aware 路由、目录实现 | J25: AdmissionRequest/Decision、截止时限（deadline）、原因（reason） code 与 回退（fallback） action | K25: 命中候选→计算 lookup/load/attach 成本→在 截止时限（deadline） 内准入或重算 | L25: 预算超时、成本不可信或水位过高时 partial/重算（recompute）；不得等待远端负收益 加载（Load） | M25: 调度器（Scheduler） 测试支架（harness） + 查询计划（QueryPlan）/目录（Directory） 桩（stub） 即可独立验收 | N25: p99 TTFT降低≥20%；废弃远端加载（abandoned remote load）降低≥50%；错误 加载（Load）<1% | O25: CONNECTOR_PROTOCOL、QUERYPLAN_ENGINE、DIRECTORY_FASTPATH 桩 | P25: SR23-02-01-01、SR23-01-03-01、SR23-02-05-02 | Q25: 否 | R25: P0 | S25: P0 | T25: 推理准入与收益决策组 | U25: =COUNTIF('追溯与覆盖'!$J$5:$J$153,A25) | V25: L1-PM-PrefixBudget-001、L1-RT-Admission-007、L1-RT-WatermarkAdmission-024 | W25: =COUNTIF('AR开发认领'!$B$5:$B$207,A25) | X25: =IF(AND(F25<>"",G25<>"",J25<>"",L25<>"",M25<>"",N25<>"",O25<>"",U25>0,W25>=3,Q25="否"),"PASS","REVIEW") | Y25: 模块性能优化｜用前缀预算（Prefix Budget）、加载与重算比较和水位准入阻断负收益请求；把命中率目标升级为正价值消费与 SLO 合格业务量。
A26: SR23-02-02-02 | B26: IR-02-02 | C26: SF-02 | D26: 缓存感知（Cache-aware） 路由与异构存储调度插件 | E26: 框架插件 | F26: cache-aware-router、vLLM/SGLang 调度器（Scheduler） 适配器（adapter） 与分层状态视图 | G26: 推理网关、vLLM/SGLang 调度器（Scheduler） | H26: 按 放置位置（Placement）/本地可用命中（Local Usable Hit） 路由、异构水位与容量感知调度 | I26: 底层对象迁移、目录存储 | J26: PlacementSummary、RouteDecision、SchedulerTierView | K26: 请求到达→查询候选位置/水位→选择实例与加载/重算策略 | L26: 目录/水位不可用时回退普通路由；系统过载时平滑拒绝 | M26: 多实例 调度器模拟器（scheduler simulator） + 目录 桩（stub） 即可独立验收 | N26: 本地可用命中（Local Usable Hit）提升≥25%；跨节点每请求字节数（bytes/request）降低≥30%；过载不崩溃 | O26: ADMISSION_ENGINE、DIRECTORY_CORE、POOL_CORE 接口桩 | P26: SR23-02-02-01、SR23-02-05-01、SR23-01-01-01 | Q26: 否 | R26: P1 | S26: P0 子集 + P1 完整 | T26: 框架调度与路由组 | U26: =COUNTIF('追溯与覆盖'!$J$5:$J$153,A26) | V26: L1-RT-CacheAwareRouting-006、L1-VLLM-HIER-SCHED-002 | W26: =COUNTIF('AR开发认领'!$B$5:$B$207,A26) | X26: =IF(AND(F26<>"",G26<>"",J26<>"",L26<>"",M26<>"",N26<>"",O26<>"",U26>0,W26>=3,Q26="否"),"PASS","REVIEW") | Y26: 模块性能优化｜基于缓存位置、可消费资格和异构存储成本进行请求路由与调度；减少跨节点字节、废弃加载和热点拥塞。
A27: SR23-02-03-01 | B27: IR-02-03 | C27: SF-02 | D27: 跨框架低时延 前缀匹配引擎（Prefix Match Engine） | E27: 组件库 | F27: prefix-match-engine、vLLM hash/SGLang RadixTree 适配器（adapter）、并发基准 | G27: 本地元数据快判、目录（Directory） 与 调度器（Scheduler） | H27: 统一 longest-prefix-match、RCU 并发、SIMD/hash 适配器（adapter） 与路径压缩 | I27: 副本位置目录、消费资格判断 | J27: match(tokens, semanticIdentity)→PrefixMatchResult | K27: 框架 token/hash 输入→本地索引匹配→返回安全前缀范围 | L27: 加速实现不可用时使用 参考匹配器（reference matcher）；不得返回未经语义校验的候选 | M27: 固定索引 测试夹具（fixture） + 并发查询即可独立验收 | N27: 查询（lookup） p99<200μs；100并发吞吐提升≥8x；匹配正确率100% | O27: CONNECTOR_PROTOCOL 的 SemanticIdentity 定义 | P27: SR23-02-01-01 | Q27: 否 | R27: P1 | S27: P0 子集 + P1 完整 | T27: 前缀算法组 | U27: =COUNTIF('追溯与覆盖'!$J$5:$J$153,A27) | V27: L1-SGL-PFX-IDX-003、L1-VLLM-PFX-SCHED-006、L1-VLLM-PFX-IDX-005 | W27: =COUNTIF('AR开发认领'!$B$5:$B$207,A27) | X27: =IF(AND(F27<>"",G27<>"",J27<>"",L27<>"",M27<>"",N27<>"",O27<>"",U27>0,W27>=3,Q27="否"),"PASS","REVIEW") | Y27: 模块性能优化｜提供跨 vLLM 哈希与 SGLang 前缀树的低时延匹配引擎；降低目录发现开销并提高并发查询吞吐，为可消费命中漏斗提供高效入口。
A28: SR23-02-04-01 | B28: IR-02-04 | C28: SF-02 | D28: 本地元数据缓存与批量快判组件 | E28: 组件库 | F28: local-metadata-cache、负缓存（Negative Cache）、批量/范围查询（Batch/Range Lookup） 和 新鲜度防护（freshness guard） | G28: 准入控制（Admission）、连接器（Connector）、目录快速路径（Directory Fastpath） | H28: 本地命中/确定 miss、元数据缓存、批量查询、可消费状态快判 | I28: 全局目录存储与副本 HA | J28: 查询（lookup）/batchLookup、NegativeResult、FreshnessEvidence | K28: 本地缓存/过滤器快判→必要时批量远端查询→返回 freshness 证据 | L28: 缓存过期或不确定时发起精确查询；禁止将 陈旧（stale） 数据作为 可用命中（usable hit） | M28: 内存数据集 + fake 远端目录（remote directory） 即可独立验收 | N28: 本地命中<10μs；确定 miss p99<5μs；远端查询QPS降低≥50%；FPR<0.1% | O28: PREFIX_ENGINE 与 DIRECTORY_CORE 桩（stub） | P28: SR23-02-03-01、SR23-02-05-01 | Q28: 否 | R28: P0 | S28: P0 | T28: 本地元数据快路径组 | U28: =COUNTIF('追溯与覆盖'!$J$5:$J$153,A28) | V28: L2-KV-ConsumeEligibility-035、L3-CONN-PFX-IDX-005、L2-CONN-META-CACHE-004、L2-PM-BatchLookup-021 | W28: =COUNTIF('AR开发认领'!$B$5:$B$207,A28) | X28: =IF(AND(F28<>"",G28<>"",J28<>"",L28<>"",M28<>"",N28<>"",O28<>"",U28>0,W28>=3,Q28="否"),"PASS","REVIEW") | Y28: 模块性能优化｜通过本地元数据缓存、确定无结果缓存（Negative Cache）和批量快判减少远端目录往返；直接优化命中/未命中的判定时延与控制面负载。
A29: SR23-02-05-01 | B29: IR-02-05 | C29: SF-02 | D29: 集群 前缀目录（PrefixDirectory） 核心与高可用服务 | E29: 独立服务 | F29: prefix-directory-service、模式（schema）、分片/复制/镜像、发布（publish）/invalidate API | G29: 连接器（Connector）、本地缓存、调度器（Scheduler）、运维 | H29: 目录 模式（schema）、原子发布、墓碑标记（tombstone）、副本位置、分片、复制与镜像 | I29: 请求级收益判断、本地 快速路径（fastpath） 实现 | J29: publish/invalidate/queryReplica、DirectoryRecord、version/墓碑标记（tombstone） | K29: 对象发布→原子写入目录→复制/镜像→查询可用副本 | L29: 主分片故障切副本；镜像过期强制精确查询；未 就绪状态（ready）/墓碑标记（tombstone） 不返回 | M29: 3节点目录集群或内存一致性模拟器即可独立验收 | N29: 可用性≥99.99%；陈旧命中（stale hit）=0；发布可见性一致；故障切换不丢记录 | O29: CONSISTENCY_SERVICE 的版本/就绪状态（ready） 语义 | P29: SR23-01-11-01 | Q29: 否 | R29: P0 | S29: P0 | T29: 分布式目录服务组 | U29: =COUNTIF('追溯与覆盖'!$J$5:$J$153,A29) | V29: L3-MS-AtomicPublishVisibility-087、L3-MS-DirectoryMirror-036、L3-MS-InvalidationTombstone-066、L3-MS-PrefixDirectorySchema-069、L3-MS-ReplicaPlacementState-059、L3-MC-PFX-REPL-004、L3-MS-DirectoryShardPolicy-073、L3-MS-MetadataCompactLayout-074、L3-MS-MultiReplicaDirectory-037 | W29: =COUNTIF('AR开发认领'!$B$5:$B$207,A29) | X29: =IF(AND(F29<>"",G29<>"",J29<>"",L29<>"",M29<>"",N29<>"",O29<>"",U29>0,W29>=3,Q29="否"),"PASS","REVIEW") | Y29: 模块功能闭包｜交付集群前缀目录（PrefixDirectory）核心与高可用服务；完成语义前缀到对象副本的发现、失效和恢复闭包，是跨节点复用的独立服务实体。
A30: SR23-02-05-02 | B30: IR-02-05 | C30: SF-02 | D30: 前缀目录（PrefixDirectory） 本地快路径与消费资格组件 | E30: 组件库 | F30: directory-fastpath、hot 本地（local） index、range/batch 查询（lookup）、ConsumeEligibility | G30: 准入控制（Admission）、查询计划（QueryPlan）、附加（Attach） | H30: 本地热索引、紧凑布局、批量查询、陈旧数据防护（stale guard）、hit quality 和消费资格 | I30: 全局分片复制、实际 KV 加载 | J30: lookupFast、ConsumeEligibilityResult、HitQuality、陈旧（stale） 原因（reason） | K30: 候选前缀→本地/镜像快查→版本/就绪状态（ready）/租约（lease） 校验→返回 usable candidates | L30: 本地证据不足时精确查询 DIRECTORY_CORE；负收益候选标记 abandoned | M30: 录制目录快照 + 故障（fault） 测试夹具（fixture） 即可独立验收 | N30: 查询（lookup） p99降低≥30%；陈旧命中（stale hit）=0；可用命中（usable hit） 转化提升≥15%；错误候选=0 | O30: DIRECTORY_CORE、LOCAL_METADATA 与 SHARED_ATTACH 契约桩 | P30: SR23-02-05-01、SR23-02-04-01、SR23-01-10-01 | Q30: 否 | R30: P0 | S30: P0 | T30: 目录快路径与资格判定组 | U30: =COUNTIF('追溯与覆盖'!$J$5:$J$153,A30) | V30: L3-MS-ConsumeEligibility-060、L3-MS-HotLocalIndex-070、L3-MS-MetadataDataPlane-035、L3-MS-RangeBatchLookup-071、L3-MS-StaleHitGuard-067、L3-MC-PFX-IDX-003、L3-MS-TTFTIndexLayout-088、L3-PM-HitQuality-023 | W30: =COUNTIF('AR开发认领'!$B$5:$B$207,A30) | X30: =IF(AND(F30<>"",G30<>"",J30<>"",L30<>"",M30<>"",N30<>"",O30<>"",U30>0,W30>=3,Q30="否"),"PASS","REVIEW") | Y30: 功能与性能协同｜完成目录本地快路径与消费资格（ConsumeEligibility）检查；在降低查询尾延迟的同时阻断版本、布局、租约、Ready 或 Rank 不一致的候选。
A31: SR23-02-06-01 | B31: IR-02-06 | C31: SF-02 | D31: KV 卸载/加载、分层回源与流式 流水线（Pipeline） | E31: 框架插件 | F31: kv-load-pipeline、vLLM/SGLang 适配器（adapter）、swap/bulk/streaming 加载（load） 控制器 | G31: 调度器（Scheduler）、准入控制（Admission）、异步有向无环图（Async DAG） 与 附加（Attach） | H31: 卸载、加载、SSD回源、page/layer 流水、批量 swap 与计算重叠 | I31: 预取概率预测、底层 提供器（Provider） 实现 | J31: LoadPlan、LayerReady、cancel/回退（fallback）、framework 适配器（adapter） | K31: 查询计划（QueryPlan）→生成 描述符（descriptor）/有向无环图（DAG）→分层加载→逐层 就绪状态（ready）→附加（Attach） | L31: 超时/路径失败时 partial/重算（recompute）；额外内存超预算时退回整段加载 | M31: 框架 测试支架（harness） + MockAsyncDAG 即可独立验收 | N31: 计算/传输重叠≥60%；换入（swap-in） TTFT降低≥25%；批量时延降低≥50%；额外内存≤15% | O31: CONNECTOR_PROTOCOL、ASYNC_DAG、SSD_BACKEND | P31: SR23-02-01-01、SR23-01-04-01、SR23-01-08-01 | Q31: 否 | R31: P2 | S31: P2 | T31: 加载流水线与框架适配组 | U31: =COUNTIF('追溯与覆盖'!$J$5:$J$153,A31) | V31: L1-SGL-PRFCH-SCHED-004、L1-SGL-SWP-XFER-002、L1-VLLM-PRFCH-SCHED-004、L2-CONN-SWP-XFER-003 | W31: =COUNTIF('AR开发认领'!$B$5:$B$207,A31) | X31: =IF(AND(F31<>"",G31<>"",J31<>"",L31<>"",M31<>"",N31<>"",O31<>"",U31>0,W31>=3,Q31="否"),"PASS","REVIEW") | Y31: 功能与性能协同｜完成 KV 卸载/加载、分层回源与流式流水线闭包；把目录和策略结果落实为可取消、可回退的真实执行路径，并提高计算—传输重叠。
A32: SR23-02-07-01 | B32: IR-02-07 | C32: SF-02 | D32: 投机预取与效果反馈组件 | E32: 策略插件 | F32: prefetch-engine、复用预测器接口、准入（admission） 反馈（feedback） 和收益看板 | G32: 调度器（Scheduler）、加载（Load） 流水线（Pipeline） 与 Tier Capacity | H32: 趋势/概率预测、预取准入、截止时限（deadline） 约束、收益反馈与误预取抑制 | I32: 项目早期复杂在线学习、底层传输执行 | J32: PrefetchCandidate、PrefetchDecision、OutcomeFeedback | K32: 生成候选→估算复用概率/成本→有界提交预取→反馈命中与浪费 | L32: 收益不稳定时只对白名单启用；高水位/前台拥塞立即暂停 | M32: 离线 追踪（trace） 回放（replay） + MockLoadPipeline 即可独立验收 | N32: 预取命中率≥70%；误预取率<20%；额外HBM≤10%；命中等待降低≥60% | O32: LOAD_PIPELINE、QUERYPLAN_ENGINE 与固定 追踪（trace） | P32: SR23-02-06-01、SR23-01-03-01 | Q32: 否 | R32: P2 | S32: P2 | T32: 预取策略组 | U32: =COUNTIF('追溯与覆盖'!$J$5:$J$153,A32) | V32: L2-CONN-PRFCH-ENGINE-007 | W32: =COUNTIF('AR开发认领'!$B$5:$B$207,A32) | X32: =IF(AND(F32<>"",G32<>"",J32<>"",L32<>"",M32<>"",N32<>"",O32<>"",U32>0,W32>=3,Q32="否"),"PASS","REVIEW") | Y32: 模块性能优化｜在功能开关下进行投机预取并闭环预测—实际效果；只有命中等待收益覆盖额外 HBM、I/O 和 TPOT 干扰时启用。
A33: SR23-02-08-01 | B33: IR-02-08 | C33: SF-02 | D33: 模型 KV 容量画像、水位与生命周期配置组件 | E33: 组件工具 | F33: capacity-profiler、模型配置画像（ModelProfile）/KV块规格（KVBlockSpec）、水位（watermark） 配置和生命周期事件 SDK | G33: 调度器（Scheduler）、Pool、Tier Capacity 与运维 | H33: 模型容量估算、水位预算、生命周期事件、defrag-aware 准入（admission） | I33: 实际迁移/压紧执行 | J33: 模型配置画像（ModelProfile）、KV块规格（KVBlockSpec）、CapacityBudget、LifecycleEvent | K33: 解析模型/布局（layout）→估算 KV 容量→生成水位/准入预算→持续校准 | L33: 画像缺失时使用保守上界；估算误差超阈值时禁止自动扩容 | M33: 模型配置与 合成分配（synthetic allocation） 即可独立验收 | N33: 容量估算误差<5%；配置校验100%；OOM/抢占（preemption）降低≥50%；错误预算=0 | O33: POOL_CORE 接口与模型配置 测试夹具（fixture） | P33: SR23-01-01-01 | Q33: 否 | R33: P0 | S33: P0 | T33: 容量画像与生命周期配置组 | U33: =COUNTIF('追溯与覆盖'!$J$5:$J$153,A33) | V33: L3-MM-Lifecycle-009、L1-MM-DefragAware-023、L1-MM-KVSizing-008 | W33: =COUNTIF('AR开发认领'!$B$5:$B$207,A33) | X33: =IF(AND(F33<>"",G33<>"",J33<>"",L33<>"",M33<>"",N33<>"",O33<>"",U33>0,W33>=3,Q33="否"),"PASS","REVIEW") | Y33: 模块功能闭包｜交付模型 KV 容量画像、水位和生命周期配置工具；统一容量口径、准入参数与采购规划，为分层策略提供可复现输入。
A34: SR23-02-09-01 | B34: IR-02-09 | C34: SF-02 | D34: 活跃/热/冷 KV 分层驻留与部分复用策略 | E34: 策略插件 | F34: residency-policy、Active/Warm/Cold classifier、部分复用边界（partial boundary） 与 视图与复制对比（View-vs-Copy） 规划器（planner） | G34: 调度器（Scheduler）、Tier Capacity、查询计划（QueryPlan） 与 加载（Load） 流水线（Pipeline） | H34: 解码阶段（Decode） 活跃状态（active） 保护、热前缀驻留、部分前缀复用、近端 视图（view）/回填选择 | I34: 物理迁移执行、目录实现 | J34: ResidencyClass、PartialReusePlan、ViewCopyDecision | K34: 分类对象→计算复用/干扰成本→生成驻留、部分复用或回填动作 | L34: 分类不可信时保护 活跃状态（active） KV 并使用保守 复制到 HBM（copy-to-HBM）；负收益则重算 | M34: 追踪（trace） 回放（replay） + MockTier/加载（Load） 即可独立验收 | N34: HBM有效容量提升≥20%；TPOT p99回退<3%；每GB 节省的令牌（saved tokens）提升≥25% | O34: CAPACITY_PROFILE、TIER_CAPACITY、LIFECYCLE_CONTROLLER | P34: SR23-02-08-01、SR23-01-01-02、SR23-01-01-03 | Q34: 否 | R34: P1 | S34: P1 | T34: 驻留与局部复用策略组 | U34: =COUNTIF('追溯与覆盖'!$J$5:$J$153,A34) | V34: L1-OL-ActiveWarmClass-010、L1-OL-PartialBoundary-012、L1-OL-ViewVsCopy-011 | W34: =COUNTIF('AR开发认领'!$B$5:$B$207,A34) | X34: =IF(AND(F34<>"",G34<>"",J34<>"",L34<>"",M34<>"",N34<>"",O34<>"",U34>0,W34>=3,Q34="否"),"PASS","REVIEW") | Y34: 模块性能优化｜按逐词生成活跃、热前缀和冷 KV 的价值进行驻留、淘汰与部分复用；提高每 GB 正价值复用和 HBM 有效容量。
A35: SR23-02-10-01 | B35: IR-02-10 | C35: SF-02 | D35: 多 并行秩（Rank） KV 一致消费与专家控制组件 | E35: 框架插件 | F35: multi-rank-coordinator、意图（Intent） API、并行秩（rank） consensus、ExpertOverride 与指标字段 | G35: TP/PP 调度器（Scheduler）、连接器（Connector）、附加（Attach） | H35: 多卡意图编排、一致消费、并行秩等待（rank wait）/失败、受控专家覆盖 | I35: 底层 collective 实现、全局调度 | J35: RankConsensus、PerRankResult、IntentOverride、semantic 指标（metrics） | K35: 广播 意图（Intent）→各 并行秩（rank） 资格检查→共识→统一 附加（Attach）/回退 | L35: 任一关键 并行秩（rank） 不一致时统一回退；expert override 必须审计且可关闭 | M35: 1/2/4 并行秩（rank） 模拟器（simulator） 即可独立验收 | N35: 正确性故障（correctness fault）=0；并行秩等待（rank wait） p99<100μs；字段覆盖100%；回退一致 | O35: CONNECTOR_PROTOCOL、SHARED_ATTACH、CONSISTENCY_SERVICE | P35: SR23-02-01-01、SR23-01-10-01、SR23-01-11-01 | Q35: 否 | R35: P0 | S35: P0 | T35: 多卡协同组 | U35: =COUNTIF('追溯与覆盖'!$J$5:$J$153,A35) | V35: L1-SE-IntentAPI-014、L1-PD-RankConsensus-013、L1-SE-ExpertOverride-015 | W35: =COUNTIF('AR开发认领'!$B$5:$B$207,A35) | X35: =IF(AND(F35<>"",G35<>"",J35<>"",L35<>"",M35<>"",N35<>"",O35<>"",U35>0,W35>=3,Q35="否"),"PASS","REVIEW") | Y35: 模块功能闭包｜完成多 Rank 的消费一致性、等待和故障控制；保证张量/流水并行场景不会因局部命中或局部 Ready 产生死锁或隐蔽错误。
A36: SR23-02-11-01 | B36: IR-02-11 | C36: SF-02 | D36: KV 全路径 遥测数据（Telemetry） 与语义指标 SDK | E36: 平台 SDK | F36: telemetry-sdk、统一字段字典、低开销 计数器/追踪（counters/traces） 和硬件 counter 适配器（adapter） | G36: 所有 L1-L4 组件、监控平台、性能基线 | H36: request/plan/object/path 关联、raw/usable/abandoned hit、主机访问（Host touch）、NPU 停顿（stall） | I36: 具体 Grafana 大盘、故障分析 UI | J36: TelemetryEvent、MetricDictionary、sampling/cardinality policy | K36: 组件上报标准事件→本地聚合/采样→导出 OTel/Prometheus | L36: 采集失败不得阻塞数据面；高基数标签限额；必要时降采样 | M36: 单进程 合成数据发射器（synthetic emitter） 即可独立验收 | N36: 字段覆盖率100%；常态探针开销<1%；核心指标丢失率<0.1% | O36: 自带 reference emitter/collector，无外部前置 | Q36: 否 | R36: P0 | S36: P0 | T36: 可观测 SDK 组 | U36: =COUNTIF('追溯与覆盖'!$J$5:$J$153,A36) | V36: L3-OB-PerPathTelemetry-047、L1-OB-SemanticMetrics-016、L4-OB-RemoteAccessCounter-057 | W36: =COUNTIF('AR开发认领'!$B$5:$B$207,A36) | X36: =IF(AND(F36<>"",G36<>"",J36<>"",L36<>"",M36<>"",N36<>"",O36<>"",U36>0,W36>=3,Q36="否"),"PASS","REVIEW") | Y36: 模块功能闭包｜交付 KV 全路径运行观测（Telemetry）与语义指标 SDK；贯通请求—计划—对象—实际路径—客户 SLO，为收益归因、策略校准和硬件反馈提供证据底座。
A37: SR23-02-11-02 | B37: IR-02-11 | C37: SF-02 | D37: 链路追踪、回退（Fallback） 分析与 KV检视工具（KVInspect） 工具 | E37: 运维工具 | F37: trace-inspect 服务/CLI、回退（fallback）/state timeline、告警与排障手册 | G37: 研发、测试、SRE 和评审验收 | H37: 路径 追踪（trace）、回退（fallback） 原因（reason）、KV 状态时间线、检视（inspect） API 与 MTTR 工作流 | I37: 通用 APM 平台替代、业务日志全文检索 | J37: TraceQuery、KVInspectResponse、FallbackTimeline、alert 模式（schema） | K37: 按 request/object/queryplan 聚合事件→重建时间线→输出根因和证据 | L37: 部分事件缺失时标记证据不足；不得生成确定性错误结论 | M37: 录制 遥测数据（telemetry） 测试夹具（fixture） 即可独立验收 | N37: 回退（fallback） 原因（reason）覆盖100%；关键路径可对账；故障定位降至分钟级 | O37: TELEMETRY_SDK 与录制事件包 | P37: SR23-02-11-01 | Q37: 否 | R37: P1 | S37: P1 | T37: 故障分析与运维工具组 | U37: =COUNTIF('追溯与覆盖'!$J$5:$J$153,A37) | V37: L2-OB-PathTrace-030、L3-FT-FallbackTrace-046、L3-OB-KVStateTrace-083、L3-CTRL-KVInspectAPI-084 | W37: =COUNTIF('AR开发认领'!$B$5:$B$207,A37) | X37: =IF(AND(F37<>"",G37<>"",J37<>"",L37<>"",M37<>"",N37<>"",O37<>"",U37>0,W37>=3,Q37="否"),"PASS","REVIEW") | Y37: 模块功能闭包｜交付链路追踪、回退分析和 KV 检查（KVInspect）工具；缩短跨框架、传输、驱动与硬件的问题定位路径，形成原厂软硬件协同系统责任闭环。
A38: SR23-02-12-01 | B38: IR-02-12 | C38: SF-02 | D38: KVCache 性能监控与告警交付包 | E38: 工程工具 | F38: Prometheus rules、Grafana 仪表板（dashboards）、分级告警与巡检手册 | G38: SRE、研发和项目验收 | H38: TTFT/TPOT/hit/path/tier/Host touch 大盘、告警和巡检 | I38: 遥测数据（Telemetry） SDK 内部埋点实现 | J38: dashboard/alert 版本包与指标字典引用 | K38: 导入标准指标→展示分位/路径/状态→触发分级告警 | L38: 指标缺失时标记不可判定；大盘故障不阻塞数据面 | M38: 录制 指标（metrics） 测试夹具（fixture） + 本地 Grafana 即可独立验收 | N38: 刷新<5s；主业务损耗<1%；告警规则准确率100% | O38: TELEMETRY_SDK 与 TRACE_INSPECT 录制数据 | P38: SR23-02-11-01、SR23-02-11-02 | Q38: 否 | R38: P1 | S38: P1 | T38: 监控与 SRE 工具组 | U38: =COUNTIF('追溯与覆盖'!$J$5:$J$153,A38) | V38: SE-MONITOR-001 | W38: =COUNTIF('AR开发认领'!$B$5:$B$207,A38) | X38: =IF(AND(F38<>"",G38<>"",J38<>"",L38<>"",M38<>"",N38<>"",O38<>"",U38>0,W38>=3,Q38="否"),"PASS","REVIEW") | Y38: 模块功能闭包｜交付性能监控与告警包，把 TTFT/TPOT、实际路径、Host CPU 零数据拷贝凭证（Host Payload Touch Bytes 严格为 0）、错误消费和资源水位转为上线可运营门禁。
A39: SR23-02-12-02 | B39: IR-02-12 | C39: SF-02 | D39: 核心组件单元/API 测试与硬件 Mock 框架 | E39: 工程工具 | F39: gtest/gmock 测试框架、硬件 Mock、符合性（conformance） 流水线（pipeline） 与覆盖率报告 | G39: 全部研发组件和 CI | H39: 单元/API/状态机 Mock、软仿分配器、覆盖率门禁 | I39: 真实多机 E2E、生产部署 | J39: test 测试夹具（fixture） SDK、mock provider API、coverage gate | K39: 组件注册 测试夹具（fixture）→执行测试→生成覆盖率/兼容性报告→门禁 | L39: 硬件不可用时使用 Mock；关键接口无 Mock 时阻断合并 | M39: 开发机/CI runner 即可独立验收 | N39: 核心覆盖率>85%；核心接口自动化通过率100% | O39: CONNECTOR_PROTOCOL、TELEMETRY_SDK 的 reference fixtures | P39: SR23-02-01-01、SR23-02-11-01 | Q39: 否 | R39: P1 | S39: P1 | T39: 自动化测试平台组 | U39: =COUNTIF('追溯与覆盖'!$J$5:$J$153,A39) | V39: SE-TEST-001 | W39: =COUNTIF('AR开发认领'!$B$5:$B$207,A39) | X39: =IF(AND(F39<>"",G39<>"",J39<>"",L39<>"",M39<>"",N39<>"",O39<>"",U39>0,W39>=3,Q39="否"),"PASS","REVIEW") | Y39: 模块功能闭包｜交付核心组件单元/API 测试与硬件模拟（Mock）框架；使 SR 在真实硬件未齐备时仍可独立验收，并沉淀 Day-0 兼容资产。
A40: SR23-02-12-03 | B40: IR-02-12 | C40: SF-02 | D40: 异构介质 E2E、长稳与混沌测试平台 | E40: 工程平台 | F40: E2E 编排、故障注入场景、72h soak suite 与恢复报告模板 | G40: 集成测试、Release 和项目验收 | H40: HBM/DDR/SSD/RDMA 连通、跨介质调度、故障回退、长稳泄漏 | I40: 日常单元测试、线上生产部署 | J40: 场景清单（scenario manifest）、故障注入（fault injection） API、证据包（evidence package） | K40: 部署测试拓扑→注入 工作负载（workload）/故障→验证恢复→归档证据 | L40: 真实硬件不足时使用受控模拟；未覆盖路径明确标记 Not Tested | M40: 最小两节点异构测试环境或等价模拟器 | N40: 72h零泄漏；故障回退（fallback）<500ms且0错误；介质连通性一键通过 | O40: UNIT_TEST_TOOL、CAP_ROUTER 与可测试 提供器（Provider） | P40: SR23-02-12-02、SR23-01-09-01 | Q40: 否 | R40: P1 | S40: P1 | T40: 系统集成与混沌测试组 | U40: =COUNTIF('追溯与覆盖'!$J$5:$J$153,A40) | V40: SE-TEST-002 | W40: =COUNTIF('AR开发认领'!$B$5:$B$207,A40) | X40: =IF(AND(F40<>"",G40<>"",J40<>"",L40<>"",M40<>"",N40<>"",O40<>"",U40>0,W40>=3,Q40="否"),"PASS","REVIEW") | Y40: 模块功能闭包｜交付异构介质端到端、长稳与混沌测试平台；用故障注入和持续运行证明正确性、回退及跨版本稳定性，而不是一次性演示。
A41: SR23-02-12-04 | B41: IR-02-12 | C41: SF-02 | D41: 跨平台构建、制品与灰度发布流水线 | E41: 工程平台 | F41: CI/CD 流水线（pipeline）、跨平台矩阵、制品库、canary/rollback 自动化 | G41: 全体研发、测试、Release 与运维 | H41: 构建、静态检查、测试触发、打包、灰度、自动回滚 | I41: 业务功能实现、云平台采购 | J41: 流水线（pipeline） templates、制品清单（artifact manifest）、发布/回滚策略（release/rollback policy） | K41: 提交→构建/检查/测试→制品→分阶灰度→发布 | L41: 任一质量门禁失败阻断；线上异常自动停止并回滚上一制品 | M41: CI runner + 测试 namespace 即可独立验收 | N41: MR反馈<15min；规范/基础错误拦截100%；自动回滚<1min | O41: UNIT_TEST_TOOL 与 E2E_CHAOS_TOOL 的可调用入口 | P41: SR23-02-12-02、SR23-02-12-03 | Q41: 否 | R41: P2 | S41: P2 | T41: 构建与发布工程组 | U41: =COUNTIF('追溯与覆盖'!$J$5:$J$153,A41) | V41: SE-CICD-001 | W41: =COUNTIF('AR开发认领'!$B$5:$B$207,A41) | X41: =IF(AND(F41<>"",G41<>"",J41<>"",L41<>"",M41<>"",N41<>"",O41<>"",U41>0,W41>=3,Q41="否"),"PASS","REVIEW") | Y41: 模块功能闭包｜交付跨平台构建、制品、灰度与回滚流水线；把 38 个 SR 组织为可独立发布、可组合认证和可快速止损的工程交付体系。
...

Sheet AR开发认领
A1: AR 开发认领（按真实复杂度拆分）
A2: 共 203 个 AR；每个 SR 按组件复杂度拆为 3～6 个工作包，不再固定“每 SR 三条”。依赖 AR 表示同一交付包内部次序，依赖 SR 表示集成依赖。
A4: AR ID | B4: 父 SR | C4: 任务类型 | D4: 任务名称 | E4: 建议责任角色 | F4: 代码/配置对象 | G4: 原子实施任务 | H4: 输出物 | I4: Definition of Done | J4: 验证命令/用例 | K4: 验收 KPI | L4: 依赖 AR | M4: 依赖 SR | N4: 优先级 | O4: 阶段 | P4: 状态 | Q4: 实际 Owner | R4: PR/Commit | S4: ID 唯一性检查 | T4: 父节点检查
A5: AR23-01-01-01-01 | B5: SR23-01-01-01 | C5: 核心实现 | D5: 统一 KV 对象池核心组件｜核心实现 | E5: 统一存储池组件组 | F5: src/pool/core/core.{h,cc} | G5: 实现“统一 KV 对象池核心组件”的可运行主路径，交付 kv-pool-core 静态/动态库、KV对象（KVObject）/存储区段清单（ExtentManifest） 数据模型及版本化 API 包 的核心代码、构建入口和最小示例。 | H5: 核心实现对应的可审查代码/IDL/配置/文档 | I5: 代码通过编译、静态检查和单元测试；接口/配置有版本；失败语义和 功能开关（feature flag） 可验证。 | J5: ctest -R pool_core && run_contract_check --sr SR23-01-01-01 | K5: 对象/存储区段（extent） 一致性错误=0；碎片率<5%；10万对象查询 p99<50μs；格式兼容测试通过率=100% | M5: SR23-01-09-01 | N5: P0 | O5: P0 | P5: 待认领 | S5: =IF(COUNTIF($A$5:$A$207,A5)=1,"PASS","FAIL") | T5: =IF(COUNTIF('SR系统设计'!$A$5:$A$42,B5)=1,"PASS","FAIL")
A6: AR23-01-01-01-02 | B6: SR23-01-01-01 | C6: 接口契约 | D6: 统一 KV 对象池核心组件｜接口契约 | E6: 统一存储池组件组 | F6: api/kvcache/v23/pool_core.proto + src/pool/core/api.{h,cc} | G6: 冻结并实现接口/IDL、版本兼容、输入输出、错误码与 消费者（consumer） 示例：KV对象存储（KVObjectStore）、存储区段清单（ExtentManifest）、放置位置（Placement）、allocate/open/close/query 接口；错误码和对象版本兼容规则 | H6: 接口契约对应的可审查代码/IDL/配置/文档 | I6: 代码通过编译、静态检查和单元测试；接口/配置有版本；失败语义和 功能开关（feature flag） 可验证。 | J6: ctest -R pool_core && run_contract_check --sr SR23-01-01-01 | K6: 对象/存储区段（extent） 一致性错误=0；碎片率<5%；10万对象查询 p99<50μs；格式兼容测试通过率=100% | L6: AR23-01-01-01-01 | M6: SR23-01-09-01 | N6: P0 | O6: P0 | P6: 待认领 | S6: =IF(COUNTIF($A$5:$A$207,A6)=1,"PASS","FAIL") | T6: =IF(COUNTIF('SR系统设计'!$A$5:$A$42,B6)=1,"PASS","FAIL")
A7: AR23-01-01-01-03 | B7: SR23-01-01-01 | C7: 状态模型 | D7: 统一 KV 对象池核心组件｜状态模型 | E7: 统一存储池组件组 | F7: src/pool/core/state_model.{h,cc} | G7: 实现状态、版本、并发互锁和持久/内存数据模型，覆盖正常转换与非法转换保护。 | H7: 状态模型对应的可审查代码/IDL/配置/文档 | I7: 代码通过编译、静态检查和单元测试；接口/配置有版本；失败语义和 功能开关（feature flag） 可验证。 | J7: ctest -R pool_core && run_contract_check --sr SR23-01-01-01 | K7: 对象/存储区段（extent） 一致性错误=0；碎片率<5%；10万对象查询 p99<50μs；格式兼容测试通过率=100% | L7: AR23-01-01-01-02 | M7: SR23-01-09-01 | N7: P0 | O7: P0 | P7: 待认领 | S7: =IF(COUNTIF($A$5:$A$207,A7)=1,"PASS","FAIL") | T7: =IF(COUNTIF('SR系统设计'!$A$5:$A$42,B7)=1,"PASS","FAIL")
A8: AR23-01-01-01-04 | B8: SR23-01-01-01 | C8: 异常回滚 | D8: 统一 KV 对象池核心组件｜异常回滚 | E8: 统一存储池组件组 | F8: src/pool/core/fallback.{h,cc} + config/feature_flags/pool_core.yaml | G8: 实现并验证失败、超时、取消、降级、回滚与关闭路径：后端能力缺失时使用 模拟后端（MockBackend）/主机内存后端（HostMemoryBackend）；分配失败显式返回 OOM/UNSUPPORTED，不隐式跨层搬运 | H8: 异常回滚对应的可审查代码/IDL/配置/文档 | I8: 代码通过编译、静态检查和单元测试；接口/配置有版本；失败语义和 功能开关（feature flag） 可验证。 | J8: ctest -R pool_core && run_contract_check --sr SR23-01-01-01 | K8: 对象/存储区段（extent） 一致性错误=0；碎片率<5%；10万对象查询 p99<50μs；格式兼容测试通过率=100% | L8: AR23-01-01-01-03 | M8: SR23-01-09-01 | N8: P0 | O8: P0 | P8: 待认领 | S8: =IF(COUNTIF($A$5:$A$207,A8)=1,"PASS","FAIL") | T8: =IF(COUNTIF('SR系统设计'!$A$5:$A$42,B8)=1,"PASS","FAIL")
A9: AR23-01-01-01-05 | B9: SR23-01-01-01 | C9: 独立验收 | D9: 统一 KV 对象池核心组件｜独立验收 | E9: 测试/验收负责人 | F9: tests/pool_core/ + benchmarks/pool_core/ + evidence/pool_core/manifest.yaml | G9: 建立不依赖全项目的验收环境，执行功能、异常、兼容和性能门禁并生成可签字证据包。 | H9: 版本化测试结果、原始证据、Go/Conditional/No-Go 结论 | I9: 在“单进程 模拟后端（MockBackend） + 文件型 SSD 仿真即可完成全套功能验收，不依赖真实集群”中完成主路径、异常、兼容和回滚；全部证据可一键复现。 | J9: run_sr_acceptance --sr SR23-01-01-01 --baseline locked | K9: 对象/存储区段（extent） 一致性错误=0；碎片率<5%；10万对象查询 p99<50μs；格式兼容测试通过率=100% | L9: AR23-01-01-01-04 | M9: SR23-01-09-01 | N9: P0 | O9: P0 | P9: 待认领 | S9: =IF(COUNTIF($A$5:$A$207,A9)=1,"PASS","FAIL") | T9: =IF(COUNTIF('SR系统设计'!$A$5:$A$42,B9)=1,"PASS","FAIL")
A10: AR23-01-01-02-01 | B10: SR23-01-01-02 | C10: 核心实现 | D10: HBM↔SSD 分层容量与 DDR 角色插件｜核心实现 | E10: 分层容量策略组 | F10: src/pool/tiering/core.{h,cc} | G10: 实现“HBM↔SSD 分层容量与 DDR 角色插件”的可运行主路径，交付 tier-capacity-policy 插件、双水位配置、DDR 角色策略（RolePolicy） 和容量收益报告 的核心代码、构建入口和最小示例。 | H10: 核心实现对应的可审查代码/IDL/配置/文档 | I10: 代码通过编译、静态检查和单元测试；接口/配置有版本；失败语义和 功能开关（feature flag） 可验证。 | J10: ctest -R tier_capacity && run_contract_check --sr SR23-01-01-02 | K10: HBM有效容量提升≥30%；OOM/抢占（preemption）降低≥50%；DDR角色必须证明净收益；策略额外开销<2% | M10: SR23-01-01-01、SR23-01-08-01 | N10: P0 | O10: P0 | P10: 待认领 | S10: =IF(COUNTIF($A$5:$A$207,A10)=1,"PASS","FAIL") | T10: =IF(COUNTIF('SR系统设计'!$A$5:$A$42,B10)=1,"PASS","FAIL")
A11: AR23-01-01-02-02 | B11: SR23-01-01-02 | C11: 接口契约 | D11: HBM↔SSD 分层容量与 DDR 角色插件｜接口契约 | E11: 分层容量策略组 | F11: api/kvcache/v23/tier_capacity.proto + src/pool/tiering/api.{h,cc} | G11: 冻结并实现接口/IDL、版本兼容、输入输出、错误码与 消费者（consumer） 示例：层级决策（TierDecision）、DDR角色决策（DDRRoleDecision）、水位快照（WatermarkSnapshot）、容量/回退原因（capacity/fallback reason） | H11: 接口契约对应的可审查代码/IDL/配置/文档 | I11: 代码通过编译、静态检查和单元测试；接口/配置有版本；失败语义和 功能开关（feature flag） 可验证。 | J11: ctest -R tier_capacity && run_contract_check --sr SR23-01-01-02 | K11: HBM有效容量提升≥30%；OOM/抢占（preemption）降低≥50%；DDR角色必须证明净收益；策略额外开销<2% | L11: AR23-01-01-02-01 | M11: SR23-01-01-01、SR23-01-08-01 | N11: P0 | O11: P0 | P11: 待认领 | S11: =IF(COUNTIF($A$5:$A$207,A11)=1,"PASS","FAIL") | T11: =IF(COUNTIF('SR系统设计'!$A$5:$A$42,B11)=1,"PASS","FAIL")
A12: AR23-01-01-02-03 | B12: SR23-01-01-02 | C12: 状态模型 | D12: HBM↔SSD 分层容量与 DDR 角色插件｜状态模型 | E12: 分层容量策略组 | F12: src/pool/tiering/state_model.{h,cc} | G12: 实现状态、版本、并发互锁和持久/内存数据模型，覆盖正常转换与非法转换保护。 | H12: 状态模型对应的可审查代码/IDL/配置/文档 | I12: 代码通过编译、静态检查和单元测试；接口/配置有版本；失败语义和 功能开关（feature flag） 可验证。 | J12: ctest -R tier_capacity && run_contract_check --sr SR23-01-01-02 | K12: HBM有效容量提升≥30%；OOM/抢占（preemption）降低≥50%；DDR角色必须证明净收益；策略额外开销<2% | L12: AR23-01-01-02-02 | M12: SR23-01-01-01、SR23-01-08-01 | N12: P0 | O12: P0 | P12: 待认领 | S12: =IF(COUNTIF($A$5:$A$207,A12)=1,"PASS","FAIL") | T12: =IF(COUNTIF('SR系统设计'!$A$5:$A$42,B12)=1,"PASS","FAIL")
A13: AR23-01-01-02-04 | B13: SR23-01-01-02 | C13: 异常回滚 | D13: HBM↔SSD 分层容量与 DDR 角色插件｜异常回滚 | E13: 分层容量策略组 | F13: src/pool/tiering/fallback.{h,cc} + config/feature_flags/tier_capacity.yaml | G13: 实现并验证失败、超时、取消、降级、回滚与关闭路径：DDR 无持续正收益时退出 有效载荷（Payload） 主路径；复杂策略不优于基线时回退双水位+hysteresis | H13: 异常回滚对应的可审查代码/IDL/配置/文档 | I13: 代码通过编译、静态检查和单元测试；接口/配置有版本；失败语义和 功能开关（feature flag） 可验证。 | J13: ctest -R tier_capacity && run_contract_check --sr SR23-01-01-02 | K13: HBM有效容量提升≥30%；OOM/抢占（preemption）降低≥50%；DDR角色必须证明净收益；策略额外开销<2% | L13: AR23-01-01-02-03 | M13: SR23-01-01-01、SR23-01-08-01 | N13: P0 | O13: P0 | P13: 待认领 | S13: =IF(COUNTIF($A$5:$A$207,A13)=1,"PASS","FAIL") | T13: =IF(COUNTIF('SR系统设计'!$A$5:$A$42,B13)=1,"PASS","FAIL")
A14: AR23-01-01-02-05 | B14: SR23-01-01-02 | C14: 独立验收 | D14: HBM↔SSD 分层容量与 DDR 角色插件｜独立验收 | E14: 测试/验收负责人 | F14: tests/tier_capacity/ + benchmarks/tier_capacity/ + evidence/tier_capacity/manifest.yaml | G14: 建立不依赖全项目的验收环境，执行功能、异常、兼容和性能门禁并生成可签字证据包。 | H14: 版本化测试结果、原始证据、Go/Conditional/No-Go 结论 | I14: 在“存储池核心（Pool Core） + SSD后端桩（SSDBackendStub） + 工作负载回放（workload replay） 即可独立验收”中完成主路径、异常、兼容和回滚；全部证据可一键复现。 | J14: run_sr_acceptance --sr SR23-01-01-02 --baseline locked | K14: HBM有效容量提升≥30%；OOM/抢占（preemption）降低≥50%；DDR角色必须证明净收益；策略额外开销<2% | L14: AR23-01-01-02-04 | M14: SR23-01-01-01、SR23-01-08-01 | N14: P0 | O14: P0 | P14: 待认领 | S14: =IF(COUNTIF($A$5:$A$207,A14)=1,"PASS","FAIL") | T14: =IF(COUNTIF('SR系统设计'!$A$5:$A$42,B14)=1,"PASS","FAIL")
